Workbook

Sheet Summary
A1: PA-07 Campaign Finance — Where the Money Is
A2: Pennsylvania's 7th congressional district · Bob Brooks (D) vs Rep. Ryan Mackenzie (R) · general election 3 November 2026. Source: FEC / OpenFEC API.
A4: DATA VINTAGE — READ THIS FIRST
A5: Candidate committee totals current through | B5: 2026-06-30 | C5: FEC Form 3, July Quarterly, filed 2026-07-15
A6: Independent expenditures current through | B6: 2026-08-19 | C6: Reported continuously — fresher than the candidate totals
A7: Data retrieved | B7: 2026-08-30T16:22:43Z | C7: Next candidate refresh: October Quarterly, ~2026-10-15
A9: MONEY AT A GLANCE
B10: Bob Brooks (D) | C10: Ryan Mackenzie (R) | D10: Mackenzie − Brooks
A11: Total receipts | B11: ='Money Sources'!B19 | C11: ='Money Sources'!C19 | D11: =IF(AND(ISNUMBER(C11),ISNUMBER(B11)),C11-B11,"")
A12: less: transfers from another committee | B12: ='Money Sources'!B20 | C12: ='Money Sources'!C20 | D12: =IF(AND(ISNUMBER(C12),ISNUMBER(B12)),C12-B12,"")
A13: Receipts excluding transfers | B13: ='Money Sources'!B21 | C13: ='Money Sources'!C21 | D13: =IF(AND(ISNUMBER(C13),ISNUMBER(B13)),C13-B13,"")
A14: Disbursements | B14: ='Money Sources'!B33 | C14: ='Money Sources'!C33 | D14: =IF(AND(ISNUMBER(C14),ISNUMBER(B14)),C14-B14,"")
A15: Cash on hand | B15: ='Money Sources'!B34 | C15: ='Money Sources'!C34 | D15: =IF(AND(ISNUMBER(C15),ISNUMBER(B15)),C15-B15,"")
A16: Debts owed | B16: ='Money Sources'!B35 | C16: ='Money Sources'!C35 | D16: =IF(AND(ISNUMBER(C16),ISNUMBER(B16)),C16-B16,"")
A17: Burn rate (disbursed ÷ raised) | B17: ='Money Sources'!B36 | C17: ='Money Sources'!C36 | D17: =IF(AND(ISNUMBER(C17),ISNUMBER(B17)),C17-B17,"")
A19: OUTSIDE MONEY (INDEPENDENT EXPENDITURES)
B20: Amount | C20: Share of all outside money | D20: Committees
A21: Total independent expenditures, all committees | B21: ='Outside Money'!D35 | C21: =IFERROR(B21/$B$21,"") | D21: ='Outside Money'!E43
A22: Supporting Bob Brooks (D) | B22: ='Outside Money'!D39 | C22: =IFERROR(B22/$B$21,"") | D22: ='Outside Money'!E39
A23: Opposing Bob Brooks (D) | B23: ='Outside Money'!D40 | C23: =IFERROR(B23/$B$21,"") | D23: ='Outside Money'!E40
A24: Supporting Ryan Mackenzie (R) | B24: ='Outside Money'!D41 | C24: =IFERROR(B24/$B$21,"") | D24: ='Outside Money'!E41
A25: Opposing Ryan Mackenzie (R) | B25: ='Outside Money'!D42 | C25: =IFERROR(B25/$B$21,"") | D25: ='Outside Money'!E42
A27: WHAT THE NUMBERS SAY
A28: Finding | B28: Figure
A29: Mackenzie's cash-on-hand advantage over Brooks | B29: =IF(AND(ISNUMBER(C15),ISNUMBER(B15)),C15-B15,"")
A30: Headline receipts gap (Mackenzie − Brooks) | B30: =IF(AND(ISNUMBER(C11),ISNUMBER(B11)),C11-B11,"")
A31: …but the gap in money actually raised this cycle, once the wound-down joint committee's transfer is set aside | B31: =IF(AND(ISNUMBER(C13),ISNUMBER(B13)),C13-B13,"")
A32: Share of Mackenzie's receipts that is that single transfer | B32: =IFERROR('Money Sources'!C20/'Money Sources'!C19,"")
A33: Total outside money in the race | B33: ='Outside Money'!D35
A34: …of which the single largest committee (STRONGER TOGETHER PA) accounts for | B34: =IFERROR('Outside Money'!D6/'Outside Money'!D35,"")
A35: Independent expenditure SUPPORTING Ryan Mackenzie — a reported absence, not missing data | B35: ='Outside Money'!D41
A36: Brooks's small-dollar (≤$200) contributions as a share of his receipts | B36: ='Money Sources'!B27
A37: Mackenzie's small-dollar (≤$200) contributions as a share of his receipts | B37: ='Money Sources'!C27
A39: TWO FACTS THE MONEY MUST BE READ WITH
A40: 1. THE TWO HALVES ARE NOT AS-OF THE SAME DATE. Candidate totals come from the July Quarterly and stop at 2026-06-30 — already about two months stale when retrieved, and widening until the October Quarterly (~15 Oct, covering through 30 Sep). Independent expenditures report continuously and are fresher. Do not compare a candidate figure and an outside-money figure as though they were measured on the same day.
A41: 2. MOST OF THIS MONEY WAS NOT SPENT ON THIS FIGHT. Of the ~$2.78M in outside spending, the two largest committees spent between 6 and 18 May 2026, inside the contested five-way DEMOCRATIC PRIMARY — not against Mackenzie. And ~$1.78M of Mackenzie's receipts is a transfer from a wound-down joint fundraising committee, not fresh donor money. The naive reading — 'Mackenzie raised $4.36M to Brooks's $2.39M' — is wrong in a way that changes the conclusion.
A43: Green figures are links to other sheets in this workbook; navy figures are computed here. Nothing on this sheet is typed in by hand — every number traces back to sources/fec.json through the Candidate Totals and Outside Money sheets.
A45: THE LAST FOUR ELECTIONS — DOES MONEY PREDICT THE RESULT?
B46: 2018 | C46: 2020 | D46: 2022 | E46: 2024
A47: Democratic share of candidate receipts | B47: ='Money vs Results'!D6 | C47: ='Money vs Results'!D7 | D47: ='Money vs Results'!D8 | E47: ='Money vs Results'!D9
...

Sheet Charts
A1: Where the Money Is — charts
A2: Every series below is linked to the data sheets. Chart source data sits in columns R–Z of this sheet. | R2: CHART 1 SOURCE — war chest
R3: Metric | S3: Bob Brooks (D) | T3: Ryan Mackenzie (R)
R4: Receipts | S4: ='Money Sources'!B32 | T4: ='Money Sources'!C32
R5: Disbursements | S5: ='Money Sources'!B33 | T5: ='Money Sources'!C33
R6: Cash on hand | S6: ='Money Sources'!B34 | T6: ='Money Sources'!C34
R8: CHART 2 SOURCE — receipts composition
R9: Candidate | S9: Individual — itemized | T9: Individual — unitemized (≤$200) | U9: PAC / other pol. cmte | V9: Party committee | W9: Transfer from other cmte | X9: Self-funding | Y9: Other / unclassified
R10: Bob Brooks (D) | S10: ='Money Sources'!B6 | T10: ='Money Sources'!B7 | U10: ='Money Sources'!B8 | V10: ='Money Sources'!B9 | W10: ='Money Sources'!B10 | X10: ='Money Sources'!B11 | Y10: ='Money Sources'!B12
R11: Ryan Mackenzie (R) | S11: ='Money Sources'!C6 | T11: ='Money Sources'!C7 | U11: ='Money Sources'!C8 | V11: ='Money Sources'!C9 | W11: ='Money Sources'!C10 | X11: ='Money Sources'!C11 | Y11: ='Money Sources'!C12
R13: CHART 3 SOURCE — headline gap vs money actually raised
R14: Measure | S14: Bob Brooks (D) | T14: Ryan Mackenzie (R)
R15: Receipts as reported | S15: ='Money Sources'!B19 | T15: ='Money Sources'!C19
R16: Receipts excluding transfers | S16: ='Money Sources'!B21 | T16: ='Money Sources'!C21
R18: CHART 4 SOURCE — ten largest outside spenders
R19: Committee | S19: Independent expenditure
R20: Stronger Together PA (supporting Brooks) | S20: ='Outside Money'!D6
R21: Lead Left PAC (opposing Brooks) | S21: ='Outside Money'!D7
R22: Jobs and Democracy PAC (supporting Brooks) | S22: ='Outside Money'!D8
R23: Congressional Progressive Caucus PAC (supporting Brooks) | S23: ='Outside Money'!D9
R24: Medicare for All (supporting Brooks) | S24: ='Outside Money'!D10
R25: DLP PAC (supporting Brooks) | S25: ='Outside Money'!D11
R26: Make the Road Action Political Committee (supporting Brooks) | S26: ='Outside Money'!D12
R27: Blue Majority Project (supporting Brooks) | S27: ='Outside Money'!D13
R28: Seniors Empowering an Effective Democracy (SEED-PAC) (supporting Brooks) | S28: ='Outside Money'!D14
R29: Blue Battleground Project (supporting Brooks) | S29: ='Outside Money'!D15
R31: CHART 5 SOURCE — outside money by target and stance
R32: Bucket | S32: Amount
R33: Supporting Brooks (D) | S33: ='Outside Money'!D39
R34: Opposing Brooks (D) | S34: ='Outside Money'!D40
R35: Supporting Mackenzie (R) | S35: ='Outside Money'!D41
R36: Opposing Mackenzie (R) | S36: ='Outside Money'!D42
R38: CHART 6 SOURCE — concentration of outside money
R39: Committee | S39: Outside spending
R40: Stronger Together PA | S40: ='Outside Money'!D6
R41: Lead Left PAC | S41: ='Outside Money'!D7
R42: Jobs and Democracy PAC | S42: ='Outside Money'!D8
R43: Congressional Progressive Caucus PAC | S43: ='Outside Money'!D9
R44: Medicare for All | S44: ='Outside Money'!D10
R45: DLP PAC | S45: ='Outside Money'!D11
...

Sheet Money Sources
A1: Where the Money Came From
A2: Composition of each nominee's receipts, and what changes when the committee transfer is set aside.
A4: SOURCE OF FUNDS
A5: Source of funds | B5: Bob Brooks (D) | C5: Ryan Mackenzie (R) | D5: Brooks — share of receipts | E5: Mackenzie — share of receipts
A6: Individual — itemized (over $200) | B6: =IFERROR(IF(INDEX('Candidate Totals'!$J$6:$J$11,MATCH("Bob Brooks",'Candidate Totals'!$A$6:$A$11,0))=0,"",INDEX('Candidate Totals'!$J$6:$J$11,MATCH("Bob Brooks",'Candidate Totals'!$A$6:$A$11,0))-INDEX('Candidate Totals'!$K$6:$K$11,MATCH("Bob Brooks",'Candidate Totals'!$A$6:$A$11,0))),"") | C6: =IFERROR(IF(INDEX('Candidate Totals'!$J$6:$J$11,MATCH("Ryan Mackenzie",'Candidate Totals'!$A$6:$A$11,0))=0,"",INDEX('Candidate Totals'!$J$6:$J$11,MATCH("Ryan Mackenzie",'Candidate Totals'!$A$6:$A$11,0))-INDEX('Candidate Totals'!$K$6:$K$11,MATCH("Ryan Mackenzie",'Candidate Totals'!$A$6:$A$11,0))),"") | D6: =IF(AND(ISNUMBER(B6),ISNUMBER(B13)),B6/B13,"") | E6: =IF(AND(ISNUMBER(C6),ISNUMBER(C13)),C6/C13,"")
A7: Individual — unitemized ($200 or less) | B7: =IFERROR(IF(INDEX('Candidate Totals'!$K$6:$K$11,MATCH("Bob Brooks",'Candidate Totals'!$A$6:$A$11,0))=0,"",INDEX('Candidate Totals'!$K$6:$K$11,MATCH("Bob Brooks",'Candidate Totals'!$A$6:$A$11,0))),"") | C7: =IFERROR(IF(INDEX('Candidate Totals'!$K$6:$K$11,MATCH("Ryan Mackenzie",'Candidate Totals'!$A$6:$A$11,0))=0,"",INDEX('Candidate Totals'!$K$6:$K$11,MATCH("Ryan Mackenzie",'Candidate Totals'!$A$6:$A$11,0))),"") | D7: =IF(AND(ISNUMBER(B7),ISNUMBER(B13)),B7/B13,"") | E7: =IF(AND(ISNUMBER(C7),ISNUMBER(C13)),C7/C13,"")
A8: PAC / other political committee | B8: =IFERROR(IF(INDEX('Candidate Totals'!$L$6:$L$11,MATCH("Bob Brooks",'Candidate Totals'!$A$6:$A$11,0))=0,"",INDEX('Candidate Totals'!$L$6:$L$11,MATCH("Bob Brooks",'Candidate Totals'!$A$6:$A$11,0))),"") | C8: =IFERROR(IF(INDEX('Candidate Totals'!$L$6:$L$11,MATCH("Ryan Mackenzie",'Candidate Totals'!$A$6:$A$11,0))=0,"",INDEX('Candidate Totals'!$L$6:$L$11,MATCH("Ryan Mackenzie",'Candidate Totals'!$A$6:$A$11,0))),"") | D8: =IF(AND(ISNUMBER(B8),ISNUMBER(B13)),B8/B13,"") | E8: =IF(AND(ISNUMBER(C8),ISNUMBER(C13)),C8/C13,"")
A9: Party committee | B9: =IFERROR(IF(INDEX('Candidate Totals'!$M$6:$M$11,MATCH("Bob Brooks",'Candidate Totals'!$A$6:$A$11,0))=0,"",INDEX('Candidate Totals'!$M$6:$M$11,MATCH("Bob Brooks",'Candidate Totals'!$A$6:$A$11,0))),"") | C9: =IFERROR(IF(INDEX('Candidate Totals'!$M$6:$M$11,MATCH("Ryan Mackenzie",'Candidate Totals'!$A$6:$A$11,0))=0,"",INDEX('Candidate Totals'!$M$6:$M$11,MATCH("Ryan Mackenzie",'Candidate Totals'!$A$6:$A$11,0))),"") | D9: =IF(AND(ISNUMBER(B9),ISNUMBER(B13)),B9/B13,"") | E9: =IF(AND(ISNUMBER(C9),ISNUMBER(C13)),C9/C13,"")
A10: Transfers from another authorized committee | B10: =IFERROR(IF(INDEX('Candidate Totals'!$N$6:$N$11,MATCH("Bob Brooks",'Candidate Totals'!$A$6:$A$11,0))=0,"",INDEX('Candidate Totals'!$N$6:$N$11,MATCH("Bob Brooks",'Candidate Totals'!$A$6:$A$11,0))),"") | C10: =IFERROR(IF(INDEX('Candidate Totals'!$N$6:$N$11,MATCH("Ryan Mackenzie",'Candidate Totals'!$A$6:$A$11,0))=0,"",INDEX('Candidate Totals'!$N$6:$N$11,MATCH("Ryan Mackenzie",'Candidate Totals'!$A$6:$A$11,0))),"") | D10: =IF(AND(ISNUMBER(B10),ISNUMBER(B13)),B10/B13,"") | E10: =IF(AND(ISNUMBER(C10),ISNUMBER(C13)),C10/C13,"")
A11: Candidate self-funding | B11: =IFERROR(INDEX('Candidate Totals'!$O$6:$O$11,MATCH("Bob Brooks",'Candidate Totals'!$A$6:$A$11,0)),"") | C11: =IFERROR(INDEX('Candidate Totals'!$O$6:$O$11,MATCH("Ryan Mackenzie",'Candidate Totals'!$A$6:$A$11,0)),"") | D11: =IF(AND(ISNUMBER(B11),ISNUMBER(B13)),B11/B13,"") | E11: =IF(AND(ISNUMBER(C11),ISNUMBER(C13)),C11/C13,"")
A12: Other / unclassified | B12: =IFERROR(IF(INDEX('Candidate Totals'!$P$6:$P$11,MATCH("Bob Brooks",'Candidate Totals'!$A$6:$A$11,0))=0,"",INDEX('Candidate Totals'!$P$6:$P$11,MATCH("Bob Brooks",'Candidate Totals'!$A$6:$A$11,0))),"") | C12: =IFERROR(IF(INDEX('Candidate Totals'!$P$6:$P$11,MATCH("Ryan Mackenzie",'Candidate Totals'!$A$6:$A$11,0))=0,"",INDEX('Candidate Totals'!$P$6:$P$11,MATCH("Ryan Mackenzie",'Candidate Totals'!$A$6:$A$11,0))),"") | D12: =IF(AND(ISNUMBER(B12),ISNUMBER(B13)),B12/B13,"") | E12: =IF(AND(ISNUMBER(C12),ISNUMBER(C13)),C12/C13,"")
A13: TOTAL RECEIPTS | B13: =SUM(B6:B12) | C13: =SUM(C6:C12) | D13: =IFERROR(SUM(D6:D12),"") | E13: =IFERROR(SUM(E6:E12),"")
A14: Reconciliation check: TOTAL RECEIPTS above is built from the components and must equal the receipts the FEC reports. The check row below recomputes the difference independently.
A15: Check: components − reported receipts (must be $0) | B15: =IFERROR(B13-INDEX('Candidate Totals'!$F$6:$F$11,MATCH("Bob Brooks",'Candidate Totals'!$A$6:$A$11,0)),"") | C15: =IFERROR(C13-INDEX('Candidate Totals'!$F$6:$F$11,MATCH("Ryan Mackenzie",'Candidate Totals'!$A$6:$A$11,0)),"")
A17: THE HEADLINE GAP, AND WHAT IS ACTUALLY IN IT
A18: Measure | B18: Bob Brooks (D) | C18: Ryan Mackenzie (R) | D18: Mackenzie − Brooks
A19: Headline receipts (as reported) | B19: =IFERROR(IF(INDEX('Candidate Totals'!$F$6:$F$11,MATCH("Bob Brooks",'Candidate Totals'!$A$6:$A$11,0))=0,"",INDEX('Candidate Totals'!$F$6:$F$11,MATCH("Bob Brooks",'Candidate Totals'!$A$6:$A$11,0))),"") | C19: =IFERROR(IF(INDEX('Candidate Totals'!$F$6:$F$11,MATCH("Ryan Mackenzie",'Candidate Totals'!$A$6:$A$11,0))=0,"",INDEX('Candidate Totals'!$F$6:$F$11,MATCH("Ryan Mackenzie",'Candidate Totals'!$A$6:$A$11,0))),"") | D19: =IF(AND(ISNUMBER(C19),ISNUMBER(B19)),C19-B19,"")
A20: less: transfers from another authorized committee | B20: =IFERROR(IF(INDEX('Candidate Totals'!$N$6:$N$11,MATCH("Bob Brooks",'Candidate Totals'!$A$6:$A$11,0))=0,"",INDEX('Candidate Totals'!$N$6:$N$11,MATCH("Bob Brooks",'Candidate Totals'!$A$6:$A$11,0))),"") | C20: =IFERROR(IF(INDEX('Candidate Totals'!$N$6:$N$11,MATCH("Ryan Mackenzie",'Candidate Totals'!$A$6:$A$11,0))=0,"",INDEX('Candidate Totals'!$N$6:$N$11,MATCH("Ryan Mackenzie",'Candidate Totals'!$A$6:$A$11,0))),"") | D20: =IF(AND(ISNUMBER(C20),ISNUMBER(B20)),C20-B20,"")
A21: Receipts excluding committee transfers | B21: =IF(AND(ISNUMBER(B19),ISNUMBER(B20)),B19-B20,"") | C21: =IF(AND(ISNUMBER(C19),ISNUMBER(C20)),C19-C20,"") | D21: =IF(AND(ISNUMBER(C21),ISNUMBER(B21)),C21-B21,"")
A22: Mackenzie's reported receipts lead Brooks by the amount in D19. Once the transfer from the wound-down joint fundraising committee is set aside, the gap in genuinely new money raised this cycle is the figure in D21 — a different race entirely.
A24: SMALL-DOLLAR RELIANCE
A25: Measure | B25: Bob Brooks (D) | C25: Ryan Mackenzie (R)
A26: Unitemized contributions ($200 or less) | B26: =IFERROR(IF(INDEX('Candidate Totals'!$K$6:$K$11,MATCH("Bob Brooks",'Candidate Totals'!$A$6:$A$11,0))=0,"",INDEX('Candidate Totals'!$K$6:$K$11,MATCH("Bob Brooks",'Candidate Totals'!$A$6:$A$11,0))),"") | C26: =IFERROR(IF(INDEX('Candidate Totals'!$K$6:$K$11,MATCH("Ryan Mackenzie",'Candidate Totals'!$A$6:$A$11,0))=0,"",INDEX('Candidate Totals'!$K$6:$K$11,MATCH("Ryan Mackenzie",'Candidate Totals'!$A$6:$A$11,0))),"")
A27: as % of total receipts | B27: =IFERROR(B26/(IFERROR(IF(INDEX('Candidate Totals'!$F$6:$F$11,MATCH("Bob Brooks",'Candidate Totals'!$A$6:$A$11,0))=0,"",INDEX('Candidate Totals'!$F$6:$F$11,MATCH("Bob Brooks",'Candidate Totals'!$A$6:$A$11,0))),"")),"") | C27: =IFERROR(C26/(IFERROR(IF(INDEX('Candidate Totals'!$F$6:$F$11,MATCH("Ryan Mackenzie",'Candidate Totals'!$A$6:$A$11,0))=0,"",INDEX('Candidate Totals'!$F$6:$F$11,MATCH("Ryan Mackenzie",'Candidate Totals'!$A$6:$A$11,0))),"")),"")
A28: as % of individual contributions | B28: =IFERROR(B26/(IFERROR(IF(INDEX('Candidate Totals'!$J$6:$J$11,MATCH("Bob Brooks",'Candidate Totals'!$A$6:$A$11,0))=0,"",INDEX('Candidate Totals'!$J$6:$J$11,MATCH("Bob Brooks",'Candidate Totals'!$A$6:$A$11,0))),"")),"") | C28: =IFERROR(C26/(IFERROR(IF(INDEX('Candidate Totals'!$J$6:$J$11,MATCH("Ryan Mackenzie",'Candidate Totals'!$A$6:$A$11,0))=0,"",INDEX('Candidate Totals'!$J$6:$J$11,MATCH("Ryan Mackenzie",'Candidate Totals'!$A$6:$A$11,0))),"")),"")
A30: SPENDING PACE AND WAR CHEST
A31: Measure | B31: Bob Brooks (D) | C31: Ryan Mackenzie (R) | D31: Mackenzie − Brooks
A32: Receipts | B32: =IFERROR(IF(INDEX('Candidate Totals'!$F$6:$F$11,MATCH("Bob Brooks",'Candidate Totals'!$A$6:$A$11,0))=0,"",INDEX('Candidate Totals'!$F$6:$F$11,MATCH("Bob Brooks",'Candidate Totals'!$A$6:$A$11,0))),"") | C32: =IFERROR(IF(INDEX('Candidate Totals'!$F$6:$F$11,MATCH("Ryan Mackenzie",'Candidate Totals'!$A$6:$A$11,0))=0,"",INDEX('Candidate Totals'!$F$6:$F$11,MATCH("Ryan Mackenzie",'Candidate Totals'!$A$6:$A$11,0))),"") | D32: =IF(AND(ISNUMBER(C32),ISNUMBER(B32)),C32-B32,"")
A33: Disbursements | B33: =IFERROR(IF(INDEX('Candidate Totals'!$G$6:$G$11,MATCH("Bob Brooks",'Candidate Totals'!$A$6:$A$11,0))=0,"",INDEX('Candidate Totals'!$G$6:$G$11,MATCH("Bob Brooks",'Candidate Totals'!$A$6:$A$11,0))),"") | C33: =IFERROR(IF(INDEX('Candidate Totals'!$G$6:$G$11,MATCH("Ryan Mackenzie",'Candidate Totals'!$A$6:$A$11,0))=0,"",INDEX('Candidate Totals'!$G$6:$G$11,MATCH("Ryan Mackenzie",'Candidate Totals'!$A$6:$A$11,0))),"") | D33: =IF(AND(ISNUMBER(C33),ISNUMBER(B33)),C33-B33,"")
A34: Cash on hand | B34: =IFERROR(IF(INDEX('Candidate Totals'!$H$6:$H$11,MATCH("Bob Brooks",'Candidate Totals'!$A$6:$A$11,0))=0,"",INDEX('Candidate Totals'!$H$6:$H$11,MATCH("Bob Brooks",'Candidate Totals'!$A$6:$A$11,0))),"") | C34: =IFERROR(IF(INDEX('Candidate Totals'!$H$6:$H$11,MATCH("Ryan Mackenzie",'Candidate Totals'!$A$6:$A$11,0))=0,"",INDEX('Candidate Totals'!$H$6:$H$11,MATCH("Ryan Mackenzie",'Candidate Totals'!$A$6:$A$11,0))),"") | D34: =IF(AND(ISNUMBER(C34),ISNUMBER(B34)),C34-B34,"")
A35: Debts owed | B35: =IFERROR(IF(INDEX('Candidate Totals'!$I$6:$I$11,MATCH("Bob Brooks",'Candidate Totals'!$A$6:$A$11,0))=0,"",INDEX('Candidate Totals'!$I$6:$I$11,MATCH("Bob Brooks",'Candidate Totals'!$A$6:$A$11,0))),"") | C35: =IFERROR(IF(INDEX('Candidate Totals'!$I$6:$I$11,MATCH("Ryan Mackenzie",'Candidate Totals'!$A$6:$A$11,0))=0,"",INDEX('Candidate Totals'!$I$6:$I$11,MATCH("Ryan Mackenzie",'Candidate Totals'!$A$6:$A$11,0))),"") | D35: =IF(AND(ISNUMBER(C35),ISNUMBER(B35)),C35-B35,"")
A36: Burn rate (disbursed ÷ raised) | B36: =IF(AND(ISNUMBER(B33),ISNUMBER(B32)),B33/B32,"") | C36: =IF(AND(ISNUMBER(C33),ISNUMBER(C32)),C33/C32,"") | D36: =IF(AND(ISNUMBER(C36),ISNUMBER(B36)),C36-B36,"")
A37: Cash on hand ÷ receipts | B37: =IF(AND(ISNUMBER(B34),ISNUMBER(B32)),B34/B32,"") | C37: =IF(AND(ISNUMBER(C34),ISNUMBER(C32)),C34/C32,"") | D37: =IF(AND(ISNUMBER(C37),ISNUMBER(B37)),C37-B37,"")
A39: Green figures are links to the Candidate Totals sheet. Black figures are computed here.
A40: Debts are amounts the committee owes; they are not netted out of cash on hand.

Sheet Candidate Totals
A1: Candidate Committee Totals — PA-07, 2026 cycle
A2: FEC Form 3 'JULY QUARTERLY 2026' (filed 2026-07-15), cycle-to-date. Coverage through 2026-06-30. Retrieved 2026-08-30T16:22:43Z.
A4: CANDIDATE TOTALS — 2026 CYCLE
A5: Candidate | B5: Party | C5: Incumbent | D5: Filed? | E5: Coverage through | F5: Receipts | G5: Disbursements | H5: Cash on hand | I5: Debts | J5: Individual — total | K5: of which: unitemized (≤$200) | L5: PAC / other pol. cmte | M5: Party committee | N5: Transfers from other auth. cmte | O5: Candidate self-funding | P5: Other / unclassified (derived)
A6: Bob Brooks | B6: DEM | C6: no | D6: yes | E6: 2026-06-30 | F6: 2392215.2 | G6: 1373792.4 | H6: 1018422.8 | I6: 15000 | J6: 1942165.5 | K6: 599386.78 | L6: 403000.03 | M6: 5000 | N6: 26085 | O6: 3500 | P6: =IF(ISNUMBER(F6),F6-(J6+L6+M6+N6+O6),"")
A7: Ryan Mackenzie | B7: REP | C7: yes | D7: yes | E7: 2026-06-30 | F7: 4357405.1 | G7: 1521927.9 | H7: 2938717.2 | I7: 22583.23 | J7: 1493241 | K7: 554133.97 | L7: 1042912.8 | M7: 5000 | N7: 1779199.1 | O7: 0 | P7: =IF(ISNUMBER(F7),F7-(J7+L7+M7+N7+O7),"")
A8: Frank Golden | B8: UN | C8: no | D8: never filed | E8: —
A9: Aiden Alexander Gonzalez | B9: DEM | C9: no | D9: never filed | E9: —
A10: Michael Ramon Granados Jr. | B10: IND | C10: no | D10: never filed | E10: —
A11: Lewis Shupe | B11: IND | C11: no | D11: never filed | E11: —
A12: TOTAL | F12: =SUM(F6:F11) | G12: =SUM(G6:G11) | H12: =SUM(H6:H11) | I12: =SUM(I6:I11) | J12: =SUM(J6:J11) | K12: =SUM(K6:K11) | L12: =SUM(L6:L11) | M12: =SUM(M6:M11) | ... P12: =SUM(P6:P11)
A14: HOW TO READ THIS TABLE
A15: • Four of the six declared candidates have never filed a periodic financial report. Their cells are BLANK, not $0 — the FEC reports no data, which is not the same as a confirmed zero. SUM() ignores blanks, so the TOTAL row is the two nominees only.
A16: • 'of which: unitemized' is a subset of 'Individual — total'. Do not add it to the other source columns; doing so double-counts.
A17: • 'Other / unclassified' is the residual: Receipts − (Individual + PAC + Party committee + Transfers + Self-funding). It is a formula, not a reported FEC field.
A18: • Mackenzie's $0 self-funding is a reported zero (rendered '—'); the blank rows above are absent data. The 'Filed?' column tells the two apart.
A19: • Blue figures are values taken directly from the FEC extraction. Black figures are computed by formula.

Sheet Outside Money
A1: Outside Money — independent expenditures, PA-07 2026
A2: OpenFEC schedules/schedule_e/by_candidate deduplicated aggregate (cycle 2026), plus one manually added 24-hour notice. Sorted largest first.
A4: INDEPENDENT EXPENDITURES
A5: Committee | B5: Target candidate | C5: Stance | D5: Amount | E5: As of | F5: Share of all outside money
A6: STRONGER TOGETHER PA | B6: Bob Brooks | C6: Support | D6: 1781524 | E6: 2026-06-30 | F6: =IFERROR(D6/$D$35,"")
A7: LEAD LEFT PAC | B7: Bob Brooks | C7: Oppose | D7: 312371.76 | E7: 2026-06-30 | F7: =IFERROR(D7/$D$35,"")
A8: JOBS AND DEMOCRACY PAC | B8: Bob Brooks | C8: Support | D8: 249750 | E8: 2026-06-30 | F8: =IFERROR(D8/$D$35,"")
A9: CONGRESSIONAL PROGRESSIVE CAUCUS PAC | B9: Bob Brooks | C9: Support | D9: 140300 | E9: 2026-06-30 | F9: =IFERROR(D9/$D$35,"")
A10: MEDICARE FOR ALL | B10: Bob Brooks | C10: Support | D10: 99625 | E10: 2026-06-30 | F10: =IFERROR(D10/$D$35,"")
A11: DLP PAC | B11: Bob Brooks | C11: Support | D11: 88321.5 | E11: 2026-06-30 | F11: =IFERROR(D11/$D$35,"")
A12: MAKE THE ROAD ACTION POLITICAL COMMITTEE | B12: Bob Brooks | C12: Support | D12: 30559.95 | E12: 2026-06-30 | F12: =IFERROR(D12/$D$35,"")
A13: BLUE MAJORITY PROJECT | B13: Bob Brooks | C13: Support | D13: 16643.34 | E13: 2026-06-30 | F13: =IFERROR(D13/$D$35,"")
A14: SENIORS EMPOWERING AN EFFECTIVE DEMOCRACY (SEED-PAC) | B14: Bob Brooks | C14: Support | D14: 11000 | E14: 2026-08-19 | F14: =IFERROR(D14/$D$35,"")
A15: BLUE BATTLEGROUND PROJECT | B15: Bob Brooks | C15: Support | D15: 9116.67 | E15: 2026-06-30 | F15: =IFERROR(D15/$D$35,"")
A16: KITCHEN TABLE VALUES PAC | B16: Bob Brooks | C16: Oppose | D16: 8840 | E16: 2026-06-30 | F16: =IFERROR(D16/$D$35,"")
A17: YOUTH SAVE DEMOCRACY PAC | B17: Ryan Mackenzie | C17: Oppose | D17: 6044 | E17: 2026-06-30 | F17: =IFERROR(D17/$D$35,"")
... A34: GIVEGREEN UNITED ACTION | B34: Bob Brooks | C34: Support | D34: 36.54 | E34: 2026-06-30 | F34: =IFERROR(D34/$D$35,"")
A35: TOTAL | D35: =SUM(D6:D34) | F35: =IFERROR(SUM(F6:F34),"")
A37: BY TARGET AND STANCE
A38: Bucket | B38: Target | C38: Stance | D38: Amount | E38: Committees | F38: Share
A39: Supporting Bob Brooks (D) | B39: Bob Brooks | C39: Support | D39: =SUMIFS($D$6:$D$34,$B$6:$B$34,B39,$C$6:$C$34,C39) | E39: =COUNTIFS($B$6:$B$34,B39,$C$6:$C$34,C39) | F39: =IFERROR(D39/$D$35,"")
A40: Opposing Bob Brooks (D) | B40: Bob Brooks | C40: Oppose | D40: =SUMIFS($D$6:$D$34,$B$6:$B$34,B40,$C$6:$C$34,C40) | E40: =COUNTIFS($B$6:$B$34,B40,$C$6:$C$34,C40) | F40: =IFERROR(D40/$D$35,"")
A41: Supporting Ryan Mackenzie (R) | B41: Ryan Mackenzie | C41: Support | D41: =SUMIFS($D$6:$D$34,$B$6:$B$34,B41,$C$6:$C$34,C41) | E41: =COUNTIFS($B$6:$B$34,B41,$C$6:$C$34,C41) | F41: =IFERROR(D41/$D$35,"")
A42: Opposing Ryan Mackenzie (R) | B42: Ryan Mackenzie | C42: Oppose | D42: =SUMIFS($D$6:$D$34,$B$6:$B$34,B42,$C$6:$C$34,C42) | E42: =COUNTIFS($B$6:$B$34,B42,$C$6:$C$34,C42) | F42: =IFERROR(D42/$D$35,"")
A43: TOTAL | D43: =SUM(D39:D42) | E43: =SUM(E39:E42) | F43: =IFERROR(D43/$D$35,"")
A45: HOW TO READ OUTSIDE MONEY
A46: • TIMING. Independent expenditures report continuously, so this table is FRESHER than the candidate totals, which stop at 2026-06-30. The two halves of this workbook are not as-of the same date.
A47: • WHAT THE MONEY WAS FOR. Spot-checks of the itemized Schedule E records for the largest committees (STRONGER TOGETHER PA, LEAD LEFT PAC) show expenditure dates clustered 2026-05-06 to 2026-05-18 — immediately before Pennsylvania's mid-May primary. Most of the money on this sheet was therefore spent inside the contested five-way DEMOCRATIC PRIMARY, not against Mackenzie in the general election.
A48: • 'Opposing Bob Brooks' is NOT the same as 'helping Ryan Mackenzie'. The largest opposing-Brooks committee (LEAD LEFT PAC, $312,371.76) spent during the Democratic primary, when Brooks's opponents were other Democrats. Do not read this bucket as Republican outside support.
A49: • Not one dollar of independent expenditure SUPPORTING Ryan Mackenzie appears in FEC records as of retrieval. The $0 in that bucket is a real, reported absence, not missing data.
A50: • DEDUPLICATION. These are OpenFEC's by_candidate aggregates, which reconcile amendments and superseding filings. A naive sum of raw itemized Schedule E line items totals roughly $5.9M — materially higher, and wrong.
A51: • The $11,000 SEED-PAC row (as of 2026-08-19) was added by hand from an itemized 24-hour notice that the aggregate endpoint had not yet absorbed. Re-check it on the next extraction to avoid double-counting.

Sheet History — Finance & Results
A1: PA-07 General Elections, 2018–2024 — Finance and Results
A2: Final full-cycle FEC committee totals and official certified vote totals. Retrieved 2026-09-07T17:37:40Z. One row per candidate per election.
A4: GENERAL-ELECTION NOMINEES — FINANCE AND RESULTS
A5: Cycle | B5: Election date | C5: District map era | D5: Candidate | E5: Party | F5: Incumbent? | G5: Receipts | H5: Disbursements | I5: Cash on hand (end of cycle) | J5: Individual contributions | K5: PAC contributions | L5: Outside $ SUPPORTING | M5: Outside $ OPPOSING | N5: Total pro-candidate resources | O5: General votes | P5: Two-party vote share | Q5: Winner | R5: Receipts per vote | S5: Total resources per vote
A6: 2018 | B6: 2018-11-06 | C6: 2018 PA Supreme Court remap (Lehigh Valley: Lehigh, Northampton, s. Monroe) | D6: Susan Wild | E6: DEM | F6: no | G6: 3320188 | H6: 3294280.3 | I6: 25907.69 | J6: 2216364.6 | K6: 535757.82 | L6: 558727.21 | M6: 221405.25 | N6: =IF(ISNUMBER(G6),G6+L6+SUMIFS($M$6:$M$13,$A$6:$A$13,$A6,$E$6:$E$13,"<>"&$E6),"") | O6: 140813 | P6: =IF(AND(ISNUMBER(O6),SUMIFS($O$6:$O$13,$A$6:$A$13,$A6)<>0),O6/SUMIFS($O$6:$O$13,$A$6:$A$13,$A6),"") | Q6: WON | R6: =IF(AND(ISNUMBER(G6),ISNUMBER(O6),O6<>0),G6/O6,"") | S6: =IF(AND(ISNUMBER(N6),ISNUMBER(O6),O6<>0),N6/O6,"")
A7: 2018 | B7: 2018-11-06 | C7: 2018 PA Supreme Court remap (Lehigh Valley: Lehigh, Northampton, s. Monroe) | D7: Marty Nothstein | E7: REP | F7: no | G7: 985643.72 | H7: 958873.74 | I7: 26769.98 | J7: 611185.92 | K7: 223856.6 | L7: 132142.37 | M7: 1722119.9 | N7: =IF(ISNUMBER(G7),G7+L7+SUMIFS($M$6:$M$13,$A$6:$A$13,$A7,$E$6:$E$13,"<>"&$E7),"") | O7: 114437 | P7: =IF(AND(ISNUMBER(O7),SUMIFS($O$6:$O$13,$A$6:$A$13,$A7)<>0),O7/SUMIFS($O$6:$O$13,$A$6:$A$13,$A7),"") | Q7: lost | R7: =IF(AND(ISNUMBER(G7),ISNUMBER(O7),O7<>0),G7/O7,"") | S7: =IF(AND(ISNUMBER(N7),ISNUMBER(O7),O7<>0),N7/O7,"")
A8: 2020 | B8: 2020-11-03 | C8: 2018 PA Supreme Court remap (Lehigh Valley: Lehigh, Northampton, s. Monroe) | D8: Susan Wild | E8: DEM | F8: yes | G8: 4644289.9 | H8: 4591501.2 | I8: 78696.36 | J8: 3417373.9 | K8: 1027682 | L8: 50133.76 | M8: 127595.71 | N8: =IF(ISNUMBER(G8),G8+L8+SUMIFS($M$6:$M$13,$A$6:$A$13,$A8,$E$6:$E$13,"<>"&$E8),"") | O8: 195475 | P8: =IF(AND(ISNUMBER(O8),SUMIFS($O$6:$O$13,$A$6:$A$13,$A8)<>0),O8/SUMIFS($O$6:$O$13,$A$6:$A$13,$A8),"") | Q8: WON | R8: =IF(AND(ISNUMBER(G8),ISNUMBER(O8),O8<>0),G8/O8,"") | S8: =IF(AND(ISNUMBER(N8),ISNUMBER(O8),O8<>0),N8/O8,"")
A9: 2020 | B9: 2020-11-03 | C9: 2018 PA Supreme Court remap (Lehigh Valley: Lehigh, Northampton, s. Monroe) | D9: Lisa Scheller | E9: REP | F9: no | G9: 3740779 | H9: 3661738.3 | I9: 79040.75 | J9: 998798.19 | K9: 231174.7 | L9: 600145.56 | M9: 1165.62 | N9: =IF(ISNUMBER(G9),G9+L9+SUMIFS($M$6:$M$13,$A$6:$A$13,$A9,$E$6:$E$13,"<>"&$E9),"") | O9: 181407 | P9: =IF(AND(ISNUMBER(O9),SUMIFS($O$6:$O$13,$A$6:$A$13,$A9)<>0),O9/SUMIFS($O$6:$O$13,$A$6:$A$13,$A9),"") | Q9: lost | R9: =IF(AND(ISNUMBER(G9),ISNUMBER(O9),O9<>0),G9/O9,"") | S9: =IF(AND(ISNUMBER(N9),ISNUMBER(O9),O9<>0),N9/O9,"")
A10: 2022 | B10: 2022-11-08 | C10: 2022 post-census remap (Lehigh, Northampton, Carbon, part of Monroe) | D10: Susan Wild | E10: DEM | F10: yes | G10: 7002291.2 | H10: 7027026.2 | I10: 53961.35 | J10: 5366116.2 | K10: 1279735.8 | L10: 654900.95 | M10: 10853652 | N10: =IF(ISNUMBER(G10),G10+L10+SUMIFS($M$6:$M$13,$A$6:$A$13,$A10,$E$6:$E$13,"<>"&$E10),"") | O10: 151364 | P10: =IF(AND(ISNUMBER(O10),SUMIFS($O$6:$O$13,$A$6:$A$13,$A10)<>0),O10/SUMIFS($O$6:$O$13,$A$6:$A$13,$A10),"") | Q10: WON | R10: =IF(AND(ISNUMBER(G10),ISNUMBER(O10),O10<>0),G10/O10,"") | S10: =IF(AND(ISNUMBER(N10),ISNUMBER(O10),O10<>0),N10/O10,"")
A11: 2022 | B11: 2022-11-08 | C11: 2022 post-census remap (Lehigh, Northampton, Carbon, part of Monroe) | D11: Lisa Scheller | E11: REP | F11: no | G11: 6354578.7 | H11: 6432421.6 | I11: 2737.49 | J11: 2381481.3 | K11: 514762 | L11: 23268.88 | M11: 8764085.8 | N11: =IF(ISNUMBER(G11),G11+L11+SUMIFS($M$6:$M$13,$A$6:$A$13,$A11,$E$6:$E$13,"<>"&$E11),"") | O11: 145527 | P11: =IF(AND(ISNUMBER(O11),SUMIFS($O$6:$O$13,$A$6:$A$13,$A11)<>0),O11/SUMIFS($O$6:$O$13,$A$6:$A$13,$A11),"") | Q11: lost | R11: =IF(AND(ISNUMBER(G11),ISNUMBER(O11),O11<>0),G11/O11,"") | S11: =IF(AND(ISNUMBER(N11),ISNUMBER(O11),O11<>0),N11/O11,"")
A12: 2024 | B12: 2024-11-05 | C12: 2022 post-census remap (Lehigh, Northampton, Carbon, part of Monroe) | D12: Susan Wild | E12: DEM | F12: yes | G12: 8960927.7 | H12: 8946230 | I12: 68659 | J12: 6604896.4 | K12: 1393265.5 | L12: 4568368.8 | M12: 10424863 | N12: =IF(ISNUMBER(G12),G12+L12+SUMIFS($M$6:$M$13,$A$6:$A$13,$A12,$E$6:$E$13,"<>"&$E12),"") | O12: 199626 | P12: =IF(AND(ISNUMBER(O12),SUMIFS($O$6:$O$13,$A$6:$A$13,$A12)<>0),O12/SUMIFS($O$6:$O$13,$A$6:$A$13,$A12),"") | Q12: lost | R12: =IF(AND(ISNUMBER(G12),ISNUMBER(O12),O12<>0),G12/O12,"") | S12: =IF(AND(ISNUMBER(N12),ISNUMBER(O12),O12<>0),N12/O12,"")
A13: 2024 | B13: 2024-11-05 | C13: 2022 post-census remap (Lehigh, Northampton, Carbon, part of Monroe) | D13: Ryan Mackenzie | E13: REP | F13: no | G13: 1818407.1 | H13: 1715167.2 | I13: 103239.91 | J13: 886645.14 | K13: 419249.05 | L13: 1333061.8 | M13: 9962854.1 | N13: =IF(ISNUMBER(G13),G13+L13+SUMIFS($M$6:$M$13,$A$6:$A$13,$A13,$E$6:$E$13,"<>"&$E13),"") | O13: 203688 | P13: =IF(AND(ISNUMBER(O13),SUMIFS($O$6:$O$13,$A$6:$A$13,$A13)<>0),O13/SUMIFS($O$6:$O$13,$A$6:$A$13,$A13),"") | Q13: WON | R13: =IF(AND(ISNUMBER(G13),ISNUMBER(O13),O13<>0),G13/O13,"") | S13: =IF(AND(ISNUMBER(N13),ISNUMBER(O13),O13<>0),N13/O13,"")
A15: TOTAL VOTES CAST, AND WHAT IS EXCLUDED FROM TWO-PARTY SHARE
A16: Cycle | O16: Total votes cast | P16: Third-party / scattered | Q16: Third-party share | R16: Vote reconciliation
A17: 2018 | D17: All candidates on the ballot | O17: 263360 | P17: 8110 | Q17: =IF(AND(ISNUMBER(O17),ISNUMBER(P17),O17<>0),P17/O17,"") | R17: =IF(NOT(ISNUMBER(O17)),"not reported",IF(ABS(SUMIF($A$6:$A$13,$A17,$O$6:$O$13)+IF(ISNUMBER(P17),P17,0)-O17)<0.5,"ok","MISMATCH"))
A18: 2020 | D18: All candidates on the ballot | O18: 377404 | P18: 522 | Q18: =IF(AND(ISNUMBER(O18),ISNUMBER(P18),O18<>0),P18/O18,"") | R18: =IF(NOT(ISNUMBER(O18)),"not reported",IF(ABS(SUMIF($A$6:$A$13,$A18,$O$6:$O$13)+IF(ISNUMBER(P18),P18,0)-O18)<0.5,"ok","MISMATCH"))
A19: 2022 | D19: All candidates on the ballot | O19: 297395 | P19: 504 | Q19: =IF(AND(ISNUMBER(O19),ISNUMBER(P19),O19<>0),P19/O19,"") | R19: =IF(NOT(ISNUMBER(O19)),"not reported",IF(ABS(SUMIF($A$6:$A$13,$A19,$O$6:$O$13)+IF(ISNUMBER(P19),P19,0)-O19)<0.5,"ok","MISMATCH"))
A20: 2024 | D20: All candidates on the ballot | Q20: =IF(AND(ISNUMBER(O20),ISNUMBER(P20),O20<>0),P20/O20,"") | R20: =IF(NOT(ISNUMBER(O20)),"not reported",IF(ABS(SUMIF($A$6:$A$13,$A20,$O$6:$O$13)+IF(ISNUMBER(P20),P20,0)-O20)<0.5,"ok","MISMATCH"))
D21: Check: two-party votes + third-party = total votes cast, for every cycle that reports one | R21: =COUNTIF(R17:R20,"MISMATCH")
A23: HOW TO READ THIS SHEET
A24: • Unlike the 2026 figures elsewhere in this workbook, these are FINAL full-cycle totals (through 31 December of each election year). They are not mid-cycle snapshots and will not change.
A25: • DISTRICT BOUNDARIES CHANGED INSIDE THIS WINDOW. 2018 and 2020 ran on the 2018 PA Supreme Court remap; 2022 and 2024 on the post-2020-census remap, which added Carbon County and altered the Monroe County portion. The seat is Lehigh Valley-based throughout, so the cycles are broadly comparable — but they are not the identical electorate, and this is the main reason to treat the trend line as indicative rather than exact.
A26: • 2018 IS THE WEAKEST DATA POINT. Susan Wild contested two races that day: the full term in the NEW PA-07 and the unexpired-term special election in the OLD PA-15. One committee financed both, so her 2018 receipts cannot be cleanly attributed to the PA-07 general. The vote figures used are the full-term (new PA-07) race.
A27: • Wild's 2018 FEC candidate record is filed under district 15, not 07. Querying the FEC for district=07, cycle=2018 returns the Republican but silently OMITS the Democratic winner. Her totals here were pulled directly by candidate ID.
A28: • 2024 THIRD-PARTY VOTES ARE UNKNOWN, NOT ZERO. The Clerk of the House summary lists only the two major-party nominees and reports no all-candidate district total, so those cells are blank and shaded. The 2018-2022 rows come from FEC files that do report an all-candidate total. Two-party vote share — what the analysis actually uses — is unaffected.
A29: • Blue figures are values from the FEC API or the official results files. Black figures are computed by formula from them.

Sheet History Charts
A1: Money and Results, 2018–2024
A2: Every series links to the History and Money vs Results sheets. Chart source data sits in columns R–V. | R2: CHART SOURCE — total money in the race
R3: Cycle | S3: Pro-Democratic money | T3: Pro-Republican money
R4: 2018 | S4: ='Money vs Results'!E6 | T4: ='Money vs Results'!F6
R5: 2020 | S5: ='Money vs Results'!E7 | T5: ='Money vs Results'!F7
R6: 2022 | S6: ='Money vs Results'!E8 | T6: ='Money vs Results'!F8
R7: 2024 | S7: ='Money vs Results'!E9 | T7: ='Money vs Results'!F9
R9: CHART SOURCE — candidate committee receipts
R10: Cycle | S10: Democratic nominee | T10: Republican nominee
R11: 2018 | S11: ='Money vs Results'!B6 | T11: ='Money vs Results'!C6
R12: 2020 | S12: ='Money vs Results'!B7 | T12: ='Money vs Results'!C7
R13: 2022 | S13: ='Money vs Results'!B8 | T13: ='Money vs Results'!C8
R14: 2024 | S14: ='Money vs Results'!B9 | T14: ='Money vs Results'!C9
R16: CHART SOURCE — resource share vs vote share (Model B)
R17: Cycle | S17: D share of total resources | T17: D two-party vote share
R18: 2018 | S18: ='Money vs Results'!G6 | T18: ='Money vs Results'!H6
R19: 2020 | S19: ='Money vs Results'!G7 | T19: ='Money vs Results'!H7
R20: 2022 | S20: ='Money vs Results'!G8 | T20: ='Money vs Results'!H8
R21: 2024 | S21: ='Money vs Results'!G9 | T21: ='Money vs Results'!H9
R23: CHART SOURCE — receipts share vs vote share (Model A)
R24: Cycle | S24: D share of candidate receipts | T24: D two-party vote share
R25: 2018 | S25: ='Money vs Results'!D6 | T25: ='Money vs Results'!H6
R26: 2020 | S26: ='Money vs Results'!D7 | T26: ='Money vs Results'!H7
R27: 2022 | S27: ='Money vs Results'!D8 | T27: ='Money vs Results'!H8
R28: 2024 | S28: ='Money vs Results'!D9 | T28: ='Money vs Results'!H9
R30: CHART SOURCE — Democratic two-party vote share
R31: Cycle | S31: D two-party vote share | T31: 50% (win threshold)
R32: 2018 | S32: ='Money vs Results'!H6 | T32: 0.5
R33: 2020 | S33: ='Money vs Results'!H7 | T33: 0.5
R34: 2022 | S34: ='Money vs Results'!H8 | T34: 0.5
R35: 2024 | S35: ='Money vs Results'!H9 | T35: 0.5
R37: CHART SOURCE — candidate money vs outside money
R38: Cycle | S38: Candidate committee money | T38: Outside money (independent expenditures)
R39: 2018 | S39: ='Money vs Results'!B6+'Money vs Results'!C6 | T39: =('Money vs Results'!E6+'Money vs Results'!F6)-('Money vs Results'!B6+'Money vs Results'!C6)
R40: 2020 | S40: ='Money vs Results'!B7+'Money vs Results'!C7 | T40: =('Money vs Results'!E7+'Money vs Results'!F7)-('Money vs Results'!B7+'Money vs Results'!C7)
R41: 2022 | S41: ='Money vs Results'!B8+'Money vs Results'!C8 | T41: =('Money vs Results'!E8+'Money vs Results'!F8)-('Money vs Results'!B8+'Money vs Results'!C8)
R42: 2024 | S42: ='Money vs Results'!B9+'Money vs Results'!C9 | T42: =('Money vs Results'!E9+'Money vs Results'!F9)-('Money vs Results'!B9+'Money vs Results'!C9)
R44: CHART SOURCE — receipts per vote received
R45: Candidate | S45: Receipts per vote
R46: 2018 Wild (D) | S46: ='History — Finance & Results'!R6
...

Sheet Money vs Results
A1: Does Money Predict the Result in PA-07?
A2: Four elections, 2018–2024. Democratic share of money against Democratic share of the two-party vote. All figures link to the History sheet.
A4: CYCLE-LEVEL SUMMARY
A5: Election cycle | B5: D candidate receipts | C5: R candidate receipts | D5: D share of candidate receipts | E5: Total pro-D resources | F5: Total pro-R resources | G5: D share of total resources | H5: D two-party vote share
A6: 2018 | B6: =SUMIFS('History — Finance & Results'!$G$6:$G$13,'History — Finance & Results'!$A$6:$A$13,$A6,'History — Finance & Results'!$E$6:$E$13,"DEM") | C6: =SUMIFS('History — Finance & Results'!$G$6:$G$13,'History — Finance & Results'!$A$6:$A$13,$A6,'History — Finance & Results'!$E$6:$E$13,"REP") | D6: =IF(B6+C6=0,"",B6/(B6+C6)) | E6: =SUMIFS('History — Finance & Results'!$N$6:$N$13,'History — Finance & Results'!$A$6:$A$13,$A6,'History — Finance & Results'!$E$6:$E$13,"DEM") | F6: =SUMIFS('History — Finance & Results'!$N$6:$N$13,'History — Finance & Results'!$A$6:$A$13,$A6,'History — Finance & Results'!$E$6:$E$13,"REP") | G6: =IF(E6+F6=0,"",E6/(E6+F6)) | H6: =SUMIFS('History — Finance & Results'!$P$6:$P$13,'History — Finance & Results'!$A$6:$A$13,$A6,'History — Finance & Results'!$E$6:$E$13,"DEM")
A7: 2020 | B7: =SUMIFS('History — Finance & Results'!$G$6:$G$13,'History — Finance & Results'!$A$6:$A$13,$A7,'History — Finance & Results'!$E$6:$E$13,"DEM") | C7: =SUMIFS('History — Finance & Results'!$G$6:$G$13,'History — Finance & Results'!$A$6:$A$13,$A7,'History — Finance & Results'!$E$6:$E$13,"REP") | D7: =IF(B7+C7=0,"",B7/(B7+C7)) | E7: =SUMIFS('History — Finance & Results'!$N$6:$N$13,'History — Finance & Results'!$A$6:$A$13,$A7,'History — Finance & Results'!$E$6:$E$13,"DEM") | F7: =SUMIFS('History — Finance & Results'!$N$6:$N$13,'History — Finance & Results'!$A$6:$A$13,$A7,'History — Finance & Results'!$E$6:$E$13,"REP") | G7: =IF(E7+F7=0,"",E7/(E7+F7)) | H7: =SUMIFS('History — Finance & Results'!$P$6:$P$13,'History — Finance & Results'!$A$6:$A$13,$A7,'History — Finance & Results'!$E$6:$E$13,"DEM")
A8: 2022 | B8: =SUMIFS('History — Finance & Results'!$G$6:$G$13,'History — Finance & Results'!$A$6:$A$13,$A8,'History — Finance & Results'!$E$6:$E$13,"DEM") | C8: =SUMIFS('History — Finance & Results'!$G$6:$G$13,'History — Finance & Results'!$A$6:$A$13,$A8,'History — Finance & Results'!$E$6:$E$13,"REP") | D8: =IF(B8+C8=0,"",B8/(B8+C8)) | E8: =SUMIFS('History — Finance & Results'!$N$6:$N$13,'History — Finance & Results'!$A$6:$A$13,$A8,'History — Finance & Results'!$E$6:$E$13,"DEM") | F8: =SUMIFS('History — Finance & Results'!$N$6:$N$13,'History — Finance & Results'!$A$6:$A$13,$A8,'History — Finance & Results'!$E$6:$E$13,"REP") | G8: =IF(E8+F8=0,"",E8/(E8+F8)) | H8: =SUMIFS('History — Finance & Results'!$P$6:$P$13,'History — Finance & Results'!$A$6:$A$13,$A8,'History — Finance & Results'!$E$6:$E$13,"DEM")
A9: 2024 | B9: =SUMIFS('History — Finance & Results'!$G$6:$G$13,'History — Finance & Results'!$A$6:$A$13,$A9,'History — Finance & Results'!$E$6:$E$13,"DEM") | C9: =SUMIFS('History — Finance & Results'!$G$6:$G$13,'History — Finance & Results'!$A$6:$A$13,$A9,'History — Finance & Results'!$E$6:$E$13,"REP") | D9: =IF(B9+C9=0,"",B9/(B9+C9)) | E9: =SUMIFS('History — Finance & Results'!$N$6:$N$13,'History — Finance & Results'!$A$6:$A$13,$A9,'History — Finance & Results'!$E$6:$E$13,"DEM") | F9: =SUMIFS('History — Finance & Results'!$N$6:$N$13,'History — Finance & Results'!$A$6:$A$13,$A9,'History — Finance & Results'!$E$6:$E$13,"REP") | G9: =IF(E9+F9=0,"",E9/(E9+F9)) | H9: =SUMIFS('History — Finance & Results'!$P$6:$P$13,'History — Finance & Results'!$A$6:$A$13,$A9,'History — Finance & Results'!$E$6:$E$13,"DEM")
A11: CORRELATION AND LINEAR REGRESSION
A12: Statistic | B12: Model A — candidate receipts only | C12: Model B — total resources (candidate + outside)
A13: Observations (n) | B13: =COUNT(H6:H9) | C13: =COUNT(H6:H9)
A14: Pearson correlation r | B14: =IFERROR(CORREL(D6:D9,H6:H9),"") | C14: =IFERROR(CORREL(G6:G9,H6:H9),"")
A15: R² (variance explained) | B15: =IFERROR(RSQ(H6:H9,D6:D9),"") | C15: =IFERROR(RSQ(H6:H9,G6:G9),"")
A16: Slope (Δ vote share per 1.0 of money share) | B16: =IFERROR(SLOPE(H6:H9,D6:D9),"") | C16: =IFERROR(SLOPE(H6:H9,G6:G9),"")
A17: Intercept | B17: =IFERROR(INTERCEPT(H6:H9,D6:D9),"") | C17: =IFERROR(INTERCEPT(H6:H9,G6:G9),"")
A18: Standard error of the slope | B18: =IFERROR(STEYX(H6:H9,D6:D9)/SQRT(DEVSQ(D6:D9)),"") | C18: =IFERROR(STEYX(H6:H9,G6:G9)/SQRT(DEVSQ(G6:G9)),"")
A19: t-statistic for the slope | B19: =IF(AND(ISNUMBER(B16),ISNUMBER(B18),B18<>0),B16/B18,"") | C19: =IF(AND(ISNUMBER(C16),ISNUMBER(C18),C18<>0),C16/C18,"")
A20: p-value (two-tailed) | B20: =IF(AND(ISNUMBER(B19),B21>0),IFERROR(TDIST(ABS(B19),B21,2),""),"") | C20: =IF(AND(ISNUMBER(C19),C21>0),IFERROR(TDIST(ABS(C19),C21,2),""),"")
A21: Degrees of freedom | B21: =IF(ISNUMBER(B13),B13-2,"") | C21: =IF(ISNUMBER(C13),C13-2,"")
A22: Statistically significant at p < 0.05? | B22: =IF(ISNUMBER(B20),IF(B20<0.05,"YES","NO — cannot reject the null"),"") | C22: =IF(ISNUMBER(C20),IF(C20<0.05,"YES","NO — cannot reject the null"),"")
A24: MODEL B — FITTED VALUES AND RESIDUALS
A25: Election cycle | B25: Actual D two-party vote share | C25: Predicted by Model B | D25: Residual (actual − predicted) | E25: D share of total resources
A26: =A6 | B26: =H6 | C26: =IF(AND(ISNUMBER($C$17),ISNUMBER($C$16),ISNUMBER(E26)),$C$17+$C$16*E26,"") | D26: =IF(AND(ISNUMBER(B26),ISNUMBER(C26)),B26-C26,"") | E26: =G6
A27: =A7 | B27: =H7 | C27: =IF(AND(ISNUMBER($C$17),ISNUMBER($C$16),ISNUMBER(E27)),$C$17+$C$16*E27,"") | D27: =IF(AND(ISNUMBER(B27),ISNUMBER(C27)),B27-C27,"") | E27: =G7
A28: =A8 | B28: =H8 | C28: =IF(AND(ISNUMBER($C$17),ISNUMBER($C$16),ISNUMBER(E28)),$C$17+$C$16*E28,"") | D28: =IF(AND(ISNUMBER(B28),ISNUMBER(C28)),B28-C28,"") | E28: =G8
A29: =A9 | B29: =H9 | C29: =IF(AND(ISNUMBER($C$17),ISNUMBER($C$16),ISNUMBER(E29)),$C$17+$C$16*E29,"") | D29: =IF(AND(ISNUMBER(B29),ISNUMBER(C29)),B29-C29,"") | E29: =G9
A31: WHAT THIS DOES AND DOES NOT ESTABLISH
A32: n = 4. THIS CANNOT SUPPORT A STATISTICAL CLAIM. With four elections and two fitted parameters there are two degrees of freedom, and the confidence interval on the slope is wider than any effect it could detect. The regression is reported because it was asked for and because it disciplines the description — not because it licenses an inference. Treat every figure above as descriptive.
A33: MODEL A IS THE ONE THAT MATTERS, AND IT FINDS NOTHING. The Democratic share of CANDIDATE fundraising has essentially no relationship to the Democratic share of the vote in this district (r² near zero). 2024 is decisive on its own: Susan Wild raised 83% of all candidate money in the race and lost it.
A34: MODEL B DOES BETTER BECAUSE IT COUNTS THE OUTSIDE MONEY. Once independent expenditures are added — including money spent attacking the opponent — the relationship turns positive and explains a meaningful share of the variance. But it is still not significant at n = 4, and the ordering is dominated by 2018, a Democratic wave year in which the Republican was barely funded.
A35: THE CAUSATION RUNS BOTH WAYS, AND MOSTLY BACKWARDS. Money flows toward races that are already expected to be close, and toward candidates already expected to win. A positive correlation between money and votes would be as consistent with 'donors can spot a winner' as with 'spending buys votes'. Nothing in this design separates the two.
A36: THE OMITTED VARIABLE IS THE NATIONAL ENVIRONMENT. 2018 was a Democratic wave; 2024 was a Republican-leaning presidential year in a district trending right. Those two facts explain the vote-share series far better than money does, and they are not in the model.

Sheet Notes & Sources
A1: Notes, Sources and Known Limitations
A2: Reproduced from sources/fec.json. Nothing here is editorial: it is the extraction's own record of what it does and does not establish.
A4: SOURCE
A5: Source: FEC / OpenFEC API
A6: URL: https://www.fec.gov/data/elections/house/PA/07/2026/
A7: Cycle: 2026
A8: Coverage through: 2026-06-30
A9: Retrieved (UTC): 2026-08-30T16:22:43Z
A10: Endpoints used: /v1/candidates/search/ · /v1/candidate/{id}/totals/ · /v1/candidate/{id}/committees/ · /v1/schedules/schedule_e/
A12: EXTRACTION NOTES
A13: • Coverage_through (2026-06-30) reflects the most recent PERIODIC financial report (FEC Form 3, 'JULY QUARTERLY 2026', filed 2026-07-15) for both major-party nominees' principal committees. As of retrieval (2026-08-30), that is roughly 2 months stale; the next scheduled disclosure is the OCTOBER QUARTERLY report (due on/around 2026-10-15, covering through 2026-09-30).
A14: • Both candidates have filed newer non-financial-summary documents since June 30, 2026 (e.g. Brooks filed a Statement of Organization amendment on 2026-08-20; both campaigns have filed periodic 48-Hour Notices of Contributions/Loans around the primary), but these do not update the aggregate receipts/disbursements/cash-on-hand totals shown here.
... A74: ! n = 4 elections. This is far too small a sample for inferential statistics; regression output in this workbook is descriptive only and is labelled as such.
