Workbook

Sheet Summary
A1: PA-07 House Election Winner — Tracker
A2: Pennsylvania's 7th Congressional District, general election 3 Nov 2026. Green = pulled from another sheet, black = calculated, blue = entered fact, yellow = key output or assumption. Built 2026-10-12 02:24 UTC.
A4: HEADLINE
A5: Consensus Democratic win probability | B5: =AVERAGE(Polymarket!D19,Kalshi!E17) | D5: Equal-weighted mean of the two venue mids. Not liquidity-weighted — Polymarket carries the larger book.
A6: Consensus Republican win probability | B6: =AVERAGE(Polymarket!D20,Kalshi!E18) | D6: Bob Brooks (D) vs incumbent Ryan Mackenzie (R).
A7: Market-implied margin (D−R) | B7: ='Margin of Victory'!B31 | D7: Expected margin from Polymarket's bracket ladder.
A9: RACE AT A GLANCE
A10: District | B10: Pennsylvania 7th (Lehigh Valley: Lehigh, Northampton, part of Monroe)
A11: Election date | B11: 46329
A12: Days until election | B12: =DATE(2026,11,3)-TODAY()
A13: Republican nominee | B13: Ryan Mackenzie (incumbent, serving since 3 Jan 2025)
A14: Democratic nominee | B14: Bob Brooks (president, PA Professional Fire Fighters Association)
A15: Democratic primary | B15: 19 May 2026 — Brooks won with ~41.4% over Crosswell, McClure, Obando-Derstine
A16: Republican primary | B16: 19 May 2026 — Mackenzie unopposed
A17: 2024 House result | B17: Mackenzie (R) 50.4% – Wild (D) 49.4% (R+1.0; narrowest PA House margin of 2024)
A18: Cook PVI | B18: R+1
A19: 2024 presidential | B19: Trump +1 (2026 GBAO sample recall: 47–46)
A20: Cook Political Report | B20: Toss Up
A21: Sabato's Crystal Ball | B21: Toss-up (moved from Lean D on 1 Feb 2026)
A22: Inside Elections | B22: Toss-up
A24: LIVE MARKET SNAPSHOT — WINNER
A25: Venue | B25: Dem Mid | C25: Rep Mid | D25: Sum of Mids | E25: Overround (vig) | F25: Dem Bid-Ask | G25: Dem Normalised | H25: Depth / Volume
A26: Polymarket | B26: =Polymarket!D19 | C26: =Polymarket!D20 | D26: =Polymarket!D21 | E26: =B26+C26-1 | F26: =Polymarket!E19 | G26: =IFERROR(B26/D26,"") | H26: =Polymarket!B12+Polymarket!C12
A27: Kalshi | B27: =Kalshi!E17 | C27: =Kalshi!E18 | D27: =Kalshi!E19 | E27: =B27+C27-1 | F27: =Kalshi!F17 | G27: =IFERROR(B27/D27,"") | H27: =Kalshi!G17+Kalshi!G18
A28: Consensus (equal weight) | B28: =AVERAGE(B26:B27) | C28: =AVERAGE(C26:C27) | D28: =AVERAGE(D26:D27) | E28: =AVERAGE(E26:E27) | F28: =AVERAGE(F26:F27) | G28: =AVERAGE(G26:G27) | H28: =SUM(H26:H27)
A30: OTHER SUBJECTS TRACKED
A31: Subject | B31: Venue | C31: Key figure | D31: Value | E31: Sheet
A32: Winner (party) | B32: Polymarket + Kalshi | C32: Consensus P(Dem) | D32: =B5 | E32: Polymarket / Kalshi
A33: Margin of victory | B33: Polymarket only | C33: Expected margin (D−R) | D33: ='Margin of Victory'!B31 | E33: Margin of Victory
A34: Margin of victory | B34: Polymarket only | C34: P(margin under 3 pts) | D34: ='Margin of Victory'!B32 | E34: Margin of Victory
A35: Voter turnout | B35: Kalshi only | C35: Expected ballots cast | D35: ='Voter Turnout'!B25 | E35: Voter Turnout
A36: PA Democratic seats | B36: Kalshi only | C36: Expected seats of 17 | D36: ='PA Seat Count'!B24 | E36: PA Seat Count
A37: Dem primary (settled) | B37: Kalshi + polls | C37: Brooks actual result | D37: =Polls!H49 | E37: Polls
A38: Kalshi also quotes a margin-of-victory ladder (KXMIDTERMMOV-PA07D/R), but too thinly to use: most rungs have no two-sided quote, so it is collected and not shown. Turnout is Kalshi-only. PA-07 still has no entry in Kalshi's closest-race market, and its PA-07 nominee and 2024 events return no tradeable markets. Full inventory on Notes & Sources.
A40: CROSS-VENUE ARBITRAGE CHECK (live, executable prices)
A41: Cheapest Dem YES ask | B41: =MIN(Polymarket!C19,Kalshi!D17) | C41: =IF(Polymarket!C19<=Kalshi!D17,"Polymarket","Kalshi")
A42: Cheapest Rep YES ask | B42: =MIN(Polymarket!C20,Kalshi!D18) | C42: =IF(Polymarket!C20<=Kalshi!D18,"Polymarket","Kalshi")
A43: Total cost of both legs | B43: =B41+B42
A44: Gross edge per $1 payout | B44: =1-B43
A45: Arbitrage present? | B45: =IF(B44>0,"YES — gross, before fees","No")
...

Sheet Charts
A1: Charts — Race Trajectory
A2: Every chart is bound to the cell ranges on the data sheets, so all of them redraw automatically each time the tracker refreshes. Built 2026-10-12 02:24 UTC.
A207: Chart 7 — the PollsMax model against Polymarket, matched day by day. The two answer the same question by different means, so a persistent gap is a claim that one of them is mispriced.
A208: Chart 1 — the headline. The dashed grey line is even odds; both venues have held Brooks above it since late April 2026.
A209: Chart 2 — a persistent gap is normal: different fees, capital costs and user bases. It is not tradeable unless the two ASK prices sum below 100%, which is the check on the Summary sheet.
A210: Chart 3 — the gap between the two lines is the bid-ask spread. A narrowing band means the market is getting more confident and more liquid.
A211: Chart 5 — a fair pair of prices sums to 100%. Below that, buying both sides locks in a profit; above it, the venue is charging a spread.

Sheet Distributions
A1: Charts — Distributions & Polls
A2: What the market thinks the result will look like, and how that squares with the polling. Built 2026-10-12 02:24 UTC.
A178: MARKETS vs POLLS — margin in percentage points
A179: Weighted poll margin | B179: =Polls!B35*100 | C179: Positive favours Brooks (D). Poll margins are scaled from fractions to points so all three bars share one axis.
A180: Adjusted poll margin | B180: =Polls!B37*100
A181: Market-implied margin | B181: ='Margin of Victory'!B31
A183: DEMOCRATIC PRIMARY — what the polls said vs what happened
A184: =Polls!A45&" ("&TEXT(Polls!E45,"d mmm")&")" | B184: =Polls!H45
A185: =Polls!A46&" ("&TEXT(Polls!E46,"d mmm")&")" | B185: =Polls!H46
A186: =Polls!A47&" ("&TEXT(Polls!E47,"d mmm")&")" | B186: =Polls!H47
A187: =Polls!A48&" ("&TEXT(Polls!E48,"d mmm")&")" | B187: =Polls!H48
A188: ACTUAL RESULT | B188: =Polls!H49
A190: Every primary poll understated Brooks, the last of them by 15 points, because 31-53% of respondents were undecided. Worth remembering when reading the single general-election poll.
A191: Chart 11 is deliberately a curve, not bars: turnout thresholds are nested, so bars would imply an exclusivity the market does not have.
A192: The margin chart mixes sources on purpose: the poll bars come from one Democratic-sponsored survey, the market bar from Polymarket's bracket ladder. Treat the gap as a question, not a signal.

Sheet Polymarket
A1: Polymarket — PA-07 House Election Winner
A2: Source: Polymarket CLOB API (clob.polymarket.com) + Gamma API. Prices are per-$1 contracts; price = implied probability. Pulled 2026-10-12 02:24 UTC.
A4: MARKET METADATA
A5: Field | B5: Democratic Party | C5: Republican Party
A6: Question | B6: Will the Democratic Party win the PA-07 House seat? | C6: Will the Republican Party win the PA-07 House seat?
A7: Market slug | B7: will-the-democratic-party-win-the-pa-07-house-seat | C7: will-the-republican-party-win-the-pa-07-house-seat
A8: CLOB token ID | B8: 37713776886536763857380242322222367371582682723176215910322979366716585040762 | C8: 56412855186822728853119072474894085602768054645914780515455268260878947887549
A9: Condition ID | B9: 0x863ec10c7b201b57ff3ca07ddbc74c5c464bb9ac732d2e003786b8455658592a | C9: 0x1a8fadca151b214722192338aa6ea3ec4122902576fb4192d7f6da3dd3a8f9ec
A10: Market opened | B10: 2025-12-16 | C10: 2025-12-16
A11: Resolution date | B11: 2026-11-04 | C11: 2026-11-04
A12: Volume ($) | B12: 25905.074 | C12: 8864.5331
A13: Liquidity ($) | B13: 22485.817 | C13: 44428.705
A14: Last trade | B14: 0.87 | C14: 0.1
A15: 24h price change
A17: LIVE ORDER BOOK SNAPSHOT
A18: Outcome | B18: Best Bid | C18: Best Ask | D18: Mid | E18: Bid-Ask Spread | F18: Bid Size ($) | G18: Ask Size ($) | H18: Implied Prob (normalised)
A19: Democratic Party | B19: 0.85 | C19: 0.87 | D19: =(B19+C19)/2 | E19: =C19-B19 | F19: 397.04 | G19: 72.57 | H19: =IFERROR(D19/$D$21,"")
A20: Republican Party | B20: 0.13 | C20: 0.14 | D20: =(B20+C20)/2 | E20: =C20-B20 | F20: 698.31 | G20: 514.7 | H20: =IFERROR(D20/$D$21,"")
A21: Sum of mids (100% = no vig) | D21: =SUM(D19:D20) | E21: =D21-1 | H21: =SUM(H19:H20)
A23: DAILY PRICE HISTORY
A24: Date | B24: Dem YES Price | C24: Rep YES Price | D24: Sum (D+R) | E24: Dem Normalised | F24: Rep Normalised | G24: Dem − Rep Spread | H24: Dem 7d Change | I24: Dem 30d Change | J24: Days to Election | K24: Axis label
A25: 46008 | B25: 0.48 | C25: 0.5 | D25: =IF(COUNT(B25:C25)=2,B25+C25,"") | E25: =IF(ISNUMBER(B25),IFERROR(B25/$D25,""),"") | F25: =IF(ISNUMBER(C25),IFERROR(C25/$D25,""),"") | G25: =IF(COUNT(B25:C25)=2,B25-C25,"") | H25: =IFERROR(IF(AND(ISNUMBER(B25),INDEX($B$25:$B25,MATCH($A25-7,$A$25:$A25,1))<>0,INDEX($A$25:$A25,MATCH($A25-7,$A$25:$A25,1))<>0,$A25-INDEX($A$25:$A25,MATCH($A25-7,$A$25:$A25,1))<=10),B25-INDEX($B$25:$B25,MATCH($A25-7,$A$25:$A25,1)),""),"") | I25: =IFERROR(IF(AND(ISNUMBER(B25),INDEX($B$25:$B25,MATCH($A25-30,$A$25:$A25,1))<>0,INDEX($A$25:$A25,MATCH($A25-30,$A$25:$A25,1))<>0,$A25-INDEX($A$25:$A25,MATCH($A25-30,$A$25:$A25,1))<=33),B25-INDEX($B$25:$B25,MATCH($A25-30,$A$25:$A25,1)),""),"") | J25: =DATE(2026,11,3)-A25 | K25: 17 Dec
A26: 46009 | B26: 0.48 | C26: 0.5 | D26: =IF(COUNT(B26:C26)=2,B26+C26,"") | E26: =IF(ISNUMBER(B26),IFERROR(B26/$D26,""),"") | F26: =IF(ISNUMBER(C26),IFERROR(C26/$D26,""),"") | G26: =IF(COUNT(B26:C26)=2,B26-C26,"") | H26: =IFERROR(IF(AND(ISNUMBER(B26),INDEX($B$25:$B26,MATCH($A26-7,$A$25:$A26,1))<>0,INDEX($A$25:$A26,MATCH($A26-7,$A$25:$A26,1))<>0,$A26-INDEX($A$25:$A26,MATCH($A26-7,$A$25:$A26,1))<=10),B26-INDEX($B$25:$B26,MATCH($A26-7,$A$25:$A26,1)),""),"") | I26: =IFERROR(IF(AND(ISNUMBER(B26),INDEX($B$25:$B26,MATCH($A26-30,$A$25:$A26,1))<>0,INDEX($A$25:$A26,MATCH($A26-30,$A$25:$A26,1))<>0,$A26-INDEX($A$25:$A26,MATCH($A26-30,$A$25:$A26,1))<=33),B26-INDEX($B$25:$B26,MATCH($A26-30,$A$25:$A26,1)),""),"") | J26: =DATE(2026,11,3)-A26 | K26: 18 Dec
A27: 46010 | B27: 0.485 | C27: 0.49 | D27: =IF(COUNT(B27:C27)=2,B27+C27,"") | E27: =IF(ISNUMBER(B27),IFERROR(B27/$D27,""),"") | F27: =IF(ISNUMBER(C27),IFERROR(C27/$D27,""),"") | G27: =IF(COUNT(B27:C27)=2,B27-C27,"") | H27: =IFERROR(IF(AND(ISNUMBER(B27),INDEX($B$25:$B27,MATCH($A27-7,$A$25:$A27,1))<>0,INDEX($A$25:$A27,MATCH($A27-7,$A$25:$A27,1))<>0,$A27-INDEX($A$25:$A27,MATCH($A27-7,$A$25:$A27,1))<=10),B27-INDEX($B$25:$B27,MATCH($A27-7,$A$25:$A27,1)),""),"") | I27: =IFERROR(IF(AND(ISNUMBER(B27),INDEX($B$25:$B27,MATCH($A27-30,$A$25:$A27,1))<>0,INDEX($A$25:$A27,MATCH($A27-30,$A$25:$A27,1))<>0,$A27-INDEX($A$25:$A27,MATCH($A27-30,$A$25:$A27,1))<=33),B27-INDEX($B$25:$B27,MATCH($A27-30,$A$25:$A27,1)),""),"") | J27: =DATE(2026,11,3)-A27 | K27: 19 Dec
A28: 46011 | B28: 0.49 | C28: 0.495 | D28: =IF(COUNT(B28:C28)=2,B28+C28,"") | E28: =IF(ISNUMBER(B28),IFERROR(B28/$D28,""),"") | F28: =IF(ISNUMBER(C28),IFERROR(C28/$D28,""),"") | G28: =IF(COUNT(B28:C28)=2,B28-C28,"") | H28: =IFERROR(IF(AND(ISNUMBER(B28),INDEX($B$25:$B28,MATCH($A28-7,$A$25:$A28,1))<>0,INDEX($A$25:$A28,MATCH($A28-7,$A$25:$A28,1))<>0,$A28-INDEX($A$25:$A28,MATCH($A28-7,$A$25:$A28,1))<=10),B28-INDEX($B$25:$B28,MATCH($A28-7,$A$25:$A28,1)),""),"") | I28: =IFERROR(IF(AND(ISNUMBER(B28),INDEX($B$25:$B28,MATCH($A28-30,$A$25:$A28,1))<>0,INDEX($A$25:$A28,MATCH($A28-30,$A$25:$A28,1))<>0,$A28-INDEX($A$25:$A28,MATCH($A28-30,$A$25:$A28,1))<=33),B28-INDEX($B$25:$B28,MATCH($A28-30,$A$25:$A28,1)),""),"") | J28: =DATE(2026,11,3)-A28 | K28: 20 Dec
A29: 46012 | B29: 0.49 | C29: 0.495 | D29: =IF(COUNT(B29:C29)=2,B29+C29,"") | E29: =IF(ISNUMBER(B29),IFERROR(B29/$D29,""),"") | F29: =IF(ISNUMBER(C29),IFERROR(C29/$D29,""),"") | G29: =IF(COUNT(B29:C29)=2,B29-C29,"") | H29: =IFERROR(IF(AND(ISNUMBER(B29),INDEX($B$25:$B29,MATCH($A29-7,$A$25:$A29,1))<>0,INDEX($A$25:$A29,MATCH($A29-7,$A$25:$A29,1))<>0,$A29-INDEX($A$25:$A29,MATCH($A29-7,$A$25:$A29,1))<=10),B29-INDEX($B$25:$B29,MATCH($A29-7,$A$25:$A29,1)),""),"") | I29: =IFERROR(IF(AND(ISNUMBER(B29),INDEX($B$25:$B29,MATCH($A29-30,$A$25:$A29,1))<>0,INDEX($A$25:$A29,MATCH($A29-30,$A$25:$A29,1))<>0,$A29-INDEX($A$25:$A29,MATCH($A29-30,$A$25:$A29,1))<=33),B29-INDEX($B$25:$B29,MATCH($A29-30,$A$25:$A29,1)),""),"") | J29: =DATE(2026,11,3)-A29 | K29: 21 Dec
A30: 46013 | B30: 0.485 | C30: 0.5 | D30: =IF(COUNT(B30:C30)=2,B30+C30,"") | E30: =IF(ISNUMBER(B30),IFERROR(B30/$D30,""),"") | F30: =IF(ISNUMBER(C30),IFERROR(C30/$D30,""),"") | G30: =IF(COUNT(B30:C30)=2,B30-C30,"") | H30: =IFERROR(IF(AND(ISNUMBER(B30),INDEX($B$25:$B30,MATCH($A30-7,$A$25:$A30,1))<>0,INDEX($A$25:$A30,MATCH($A30-7,$A$25:$A30,1))<>0,$A30-INDEX($A$25:$A30,MATCH($A30-7,$A$25:$A30,1))<=10),B30-INDEX($B$25:$B30,MATCH($A30-7,$A$25:$A30,1)),""),"") | I30: =IFERROR(IF(AND(ISNUMBER(B30),INDEX($B$25:$B30,MATCH($A30-30,$A$25:$A30,1))<>0,INDEX($A$25:$A30,MATCH($A30-30,$A$25:$A30,1))<>0,$A30-INDEX($A$25:$A30,MATCH($A30-30,$A$25:$A30,1))<=33),B30-INDEX($B$25:$B30,MATCH($A30-30,$A$25:$A30,1)),""),"") | J30: =DATE(2026,11,3)-A30 | K30: 22 Dec
A31: 46014 | B31: 0.495 | C31: 0.5 | D31: =IF(COUNT(B31:C31)=2,B31+C31,"") | E31: =IF(ISNUMBER(B31),IFERROR(B31/$D31,""),"") | F31: =IF(ISNUMBER(C31),IFERROR(C31/$D31,""),"") | G31: =IF(COUNT(B31:C31)=2,B31-C31,"") | H31: =IFERROR(IF(AND(ISNUMBER(B31),INDEX($B$25:$B31,MATCH($A31-7,$A$25:$A31,1))<>0,INDEX($A$25:$A31,MATCH($A31-7,$A$25:$A31,1))<>0,$A31-INDEX($A$25:$A31,MATCH($A31-7,$A$25:$A31,1))<=10),B31-INDEX($B$25:$B31,MATCH($A31-7,$A$25:$A31,1)),""),"") | I31: =IFERROR(IF(AND(ISNUMBER(B31),INDEX($B$25:$B31,MATCH($A31-30,$A$25:$A31,1))<>0,INDEX($A$25:$A31,MATCH($A31-30,$A$25:$A31,1))<>0,$A31-INDEX($A$25:$A31,MATCH($A31-30,$A$25:$A31,1))<=33),B31-INDEX($B$25:$B31,MATCH($A31-30,$A$25:$A31,1)),""),"") | J31: =DATE(2026,11,3)-A31 | K31: 23 Dec
A32: 46015 | B32: 0.49 | C32: 0.5 | D32: =IF(COUNT(B32:C32)=2,B32+C32,"") | E32: =IF(ISNUMBER(B32),IFERROR(B32/$D32,""),"") | F32: =IF(ISNUMBER(C32),IFERROR(C32/$D32,""),"") | G32: =IF(COUNT(B32:C32)=2,B32-C32,"") | H32: =IFERROR(IF(AND(ISNUMBER(B32),INDEX($B$25:$B32,MATCH($A32-7,$A$25:$A32,1))<>0,INDEX($A$25:$A32,MATCH($A32-7,$A$25:$A32,1))<>0,$A32-INDEX($A$25:$A32,MATCH($A32-7,$A$25:$A32,1))<=10),B32-INDEX($B$25:$B32,MATCH($A32-7,$A$25:$A32,1)),""),"") | I32: =IFERROR(IF(AND(ISNUMBER(B32),INDEX($B$25:$B32,MATCH($A32-30,$A$25:$A32,1))<>0,INDEX($A$25:$A32,MATCH($A32-30,$A$25:$A32,1))<>0,$A32-INDEX($A$25:$A32,MATCH($A32-30,$A$25:$A32,1))<=33),B32-INDEX($B$25:$B32,MATCH($A32-30,$A$25:$A32,1)),""),"") | J32: =DATE(2026,11,3)-A32 | K32: 24 Dec
A33: 46016 | B33: 0.49 | C33: 0.49 | D33: =IF(COUNT(B33:C33)=2,B33+C33,"") | E33: =IF(ISNUMBER(B33),IFERROR(B33/$D33,""),"") | F33: =IF(ISNUMBER(C33),IFERROR(C33/$D33,""),"") | G33: =IF(COUNT(B33:C33)=2,B33-C33,"") | H33: =IFERROR(IF(AND(ISNUMBER(B33),INDEX($B$25:$B33,MATCH($A33-7,$A$25:$A33,1))<>0,INDEX($A$25:$A33,MATCH($A33-7,$A$25:$A33,1))<>0,$A33-INDEX($A$25:$A33,MATCH($A33-7,$A$25:$A33,1))<=10),B33-INDEX($B$25:$B33,MATCH($A33-7,$A$25:$A33,1)),""),"") | I33: =IFERROR(IF(AND(ISNUMBER(B33),INDEX($B$25:$B33,MATCH($A33-30,$A$25:$A33,1))<>0,INDEX($A$25:$A33,MATCH($A33-30,$A$25:$A33,1))<>0,$A33-INDEX($A$25:$A33,MATCH($A33-30,$A$25:$A33,1))<=33),B33-INDEX($B$25:$B33,MATCH($A33-30,$A$25:$A33,1)),""),"") | J33: =DATE(2026,11,3)-A33 | K33: 25 Dec
A34: 46017 | B34: 0.49 | C34: 0.495 | D34: =IF(COUNT(B34:C34)=2,B34+C34,"") | E34: =IF(ISNUMBER(B34),IFERROR(B34/$D34,""),"") | F34: =IF(ISNUMBER(C34),IFERROR(C34/$D34,""),"") | G34: =IF(COUNT(B34:C34)=2,B34-C34,"") | H34: =IFERROR(IF(AND(ISNUMBER(B34),INDEX($B$25:$B34,MATCH($A34-7,$A$25:$A34,1))<>0,INDEX($A$25:$A34,MATCH($A34-7,$A$25:$A34,1))<>0,$A34-INDEX($A$25:$A34,MATCH($A34-7,$A$25:$A34,1))<=10),B34-INDEX($B$25:$B34,MATCH($A34-7,$A$25:$A34,1)),""),"") | I34: =IFERROR(IF(AND(ISNUMBER(B34),INDEX($B$25:$B34,MATCH($A34-30,$A$25:$A34,1))<>0,INDEX($A$25:$A34,MATCH($A34-30,$A$25:$A34,1))<>0,$A34-INDEX($A$25:$A34,MATCH($A34-30,$A$25:$A34,1))<=33),B34-INDEX($B$25:$B34,MATCH($A34-30,$A$25:$A34,1)),""),"") | J34: =DATE(2026,11,3)-A34 | K34: 26 Dec
A35: 46018 | B35: 0.495 | C35: 0.5 | D35: =IF(COUNT(B35:C35)=2,B35+C35,"") | E35: =IF(ISNUMBER(B35),IFERROR(B35/$D35,""),"") | F35: =IF(ISNUMBER(C35),IFERROR(C35/$D35,""),"") | G35: =IF(COUNT(B35:C35)=2,B35-C35,"") | H35: =IFERROR(IF(AND(ISNUMBER(B35),INDEX($B$25:$B35,MATCH($A35-7,$A$25:$A35,1))<>0,INDEX($A$25:$A35,MATCH($A35-7,$A$25:$A35,1))<>0,$A35-INDEX($A$25:$A35,MATCH($A35-7,$A$25:$A35,1))<=10),B35-INDEX($B$25:$B35,MATCH($A35-7,$A$25:$A35,1)),""),"") | I35: =IFERROR(IF(AND(ISNUMBER(B35),INDEX($B$25:$B35,MATCH($A35-30,$A$25:$A35,1))<>0,INDEX($A$25:$A35,MATCH($A35-30,$A$25:$A35,1))<>0,$A35-INDEX($A$25:$A35,MATCH($A35-30,$A$25:$A35,1))<=33),B35-INDEX($B$25:$B35,MATCH($A35-30,$A$25:$A35,1)),""),"") | J35: =DATE(2026,11,3)-A35 | K35: 27 Dec
A36: 46019 | B36: 0.485 | C36: 0.495 | D36: =IF(COUNT(B36:C36)=2,B36+C36,"") | E36: =IF(ISNUMBER(B36),IFERROR(B36/$D36,""),"") | F36: =IF(ISNUMBER(C36),IFERROR(C36/$D36,""),"") | G36: =IF(COUNT(B36:C36)=2,B36-C36,"") | H36: =IFERROR(IF(AND(ISNUMBER(B36),INDEX($B$25:$B36,MATCH($A36-7,$A$25:$A36,1))<>0,INDEX($A$25:$A36,MATCH($A36-7,$A$25:$A36,1))<>0,$A36-INDEX($A$25:$A36,MATCH($A36-7,$A$25:$A36,1))<=10),B36-INDEX($B$25:$B36,MATCH($A36-7,$A$25:$A36,1)),""),"") | I36: =IFERROR(IF(AND(ISNUMBER(B36),INDEX($B$25:$B36,MATCH($A36-30,$A$25:$A36,1))<>0,INDEX($A$25:$A36,MATCH($A36-30,$A$25:$A36,1))<>0,$A36-INDEX($A$25:$A36,MATCH($A36-30,$A$25:$A36,1))<=33),B36-INDEX($B$25:$B36,MATCH($A36-30,$A$25:$A36,1)),""),"") | J36: =DATE(2026,11,3)-A36 | K36: 28 Dec
... A128: 46121 | B128: 0.735 | C128: 0.265 | D128: =IF(COUNT(B128:C128)=2,B128+C128,"") | E128: =IF(ISNUMBER(B128),IFERROR(B128/$D128,""),"") | F128: =IF(ISNUMBER(C128),IFERROR(C128/$D128,""),"") | G128: =IF(COUNT(B128:C128)=2,B128-C128,"") | H128: =IFERROR(IF(AND(ISNUMBER(B128),INDEX($B$25:$B128,MATCH($A128-7,$A$25:$A128,1))<>0,INDEX($A$25:$A128,MATCH($A128-7,$A$25:$A128,1))<>0,$A128-INDEX($A$25:$A128,MATCH($A128-7,$A$25:$A128,1))<=10),B128-INDEX($B$25:$B128,MATCH($A128-7,$A$25:$A128,1)),""),"") | I128: =IFERROR(IF(AND(ISNUMBER(B128),INDEX($B$25:$B128,MATCH($A128-30,$A$25:$A128,1))<>0,INDEX($A$25:$A128,MATCH($A128-30,$A$25:$A128,1))<>0,$A128-INDEX($A$25:$A128,MATCH($A128-30,$A$25:$A128,1))<=33),B128-INDEX($B$25:$B128,MATCH($A128-30,$A$25:$A128,1)),""),"") | J128: =DATE(2026,11,3)-A128 | K128: 09 Apr
A129: 46130 | B129: 0.745 | D129: =IF(COUNT(B129:C129)=2,B129+C129,"") | E129: =IF(ISNUMBER(B129),IFERROR(B129/$D129,""),"") | F129: =IF(ISNUMBER(C129),IFERROR(C129/$D129,""),"") | G129: =IF(COUNT(B129:C129)=2,B129-C129,"") | H129: =IFERROR(IF(AND(ISNUMBER(B129),INDEX($B$25:$B129,MATCH($A129-7,$A$25:$A129,1))<>0,INDEX($A$25:$A129,MATCH($A129-7,$A$25:$A129,1))<>0,$A129-INDEX($A$25:$A129,MATCH($A129-7,$A$25:$A129,1))<=10),B129-INDEX($B$25:$B129,MATCH($A129-7,$A$25:$A129,1)),""),"") | I129: =IFERROR(IF(AND(ISNUMBER(B129),INDEX($B$25:$B129,MATCH($A129-30,$A$25:$A129,1))<>0,INDEX($A$25:$A129,MATCH($A129-30,$A$25:$A129,1))<>0,$A129-INDEX($A$25:$A129,MATCH($A129-30,$A$25:$A129,1))<=33),B129-INDEX($B$25:$B129,MATCH($A129-30,$A$25:$A129,1)),""),"") | J129: =DATE(2026,11,3)-A129 | K129: 18 Apr
A130: 46134 | B130: 0.715 | C130: 0.29 | D130: =IF(COUNT(B130:C130)=2,B130+C130,"") | E130: =IF(ISNUMBER(B130),IFERROR(B130/$D130,""),"") | F130: =IF(ISNUMBER(C130),IFERROR(C130/$D130,""),"") | G130: =IF(COUNT(B130:C130)=2,B130-C130,"") | H130: =IFERROR(IF(AND(ISNUMBER(B130),INDEX($B$25:$B130,MATCH($A130-7,$A$25:$A130,1))<>0,INDEX($A$25:$A130,MATCH($A130-7,$A$25:$A130,1))<>0,$A130-INDEX($A$25:$A130,MATCH($A130-7,$A$25:$A130,1))<=10),B130-INDEX($B$25:$B130,MATCH($A130-7,$A$25:$A130,1)),""),"") | I130: =IFERROR(IF(AND(ISNUMBER(B130),INDEX($B$25:$B130,MATCH($A130-30,$A$25:$A130,1))<>0,INDEX($A$25:$A130,MATCH($A130-30,$A$25:$A130,1))<>0,$A130-INDEX($A$25:$A130,MATCH($A130-30,$A$25:$A130,1))<=33),B130-INDEX($B$25:$B130,MATCH($A130-30,$A$25:$A130,1)),""),"") | J130: =DATE(2026,11,3)-A130 | K130: 22 Apr
A131: 46135 | B131: 0.67 | C131: 0.24 | D131: =IF(COUNT(B131:C131)=2,B131+C131,"") | E131: =IF(ISNUMBER(B131),IFERROR(B131/$D131,""),"") | F131: =IF(ISNUMBER(C131),IFERROR(C131/$D131,""),"") | G131: =IF(COUNT(B131:C131)=2,B131-C131,"") | H131: =IFERROR(IF(AND(ISNUMBER(B131),INDEX($B$25:$B131,MATCH($A131-7,$A$25:$A131,1))<>0,INDEX($A$25:$A131,MATCH($A131-7,$A$25:$A131,1))<>0,$A131-INDEX($A$25:$A131,MATCH($A131-7,$A$25:$A131,1))<=10),B131-INDEX($B$25:$B131,MATCH($A131-7,$A$25:$A131,1)),""),"") | I131: =IFERROR(IF(AND(ISNUMBER(B131),INDEX($B$25:$B131,MATCH($A131-30,$A$25:$A131,1))<>0,INDEX($A$25:$A131,MATCH($A131-30,$A$25:$A131,1))<>0,$A131-INDEX($A$25:$A131,MATCH($A131-30,$A$25:$A131,1))<=33),B131-INDEX($B$25:$B131,MATCH($A131-30,$A$25:$A131,1)),""),"") | J131: =DATE(2026,11,3)-A131 | K131: 23 Apr
A132: 46136 | B132: 0.685 | C132: 0.245 | D132: =IF(COUNT(B132:C132)=2,B132+C132,"") | E132: =IF(ISNUMBER(B132),IFERROR(B132/$D132,""),"") | F132: =IF(ISNUMBER(C132),IFERROR(C132/$D132,""),"") | G132: =IF(COUNT(B132:C132)=2,B132-C132,"") | H132: =IFERROR(IF(AND(ISNUMBER(B132),INDEX($B$25:$B132,MATCH($A132-7,$A$25:$A132,1))<>0,INDEX($A$25:$A132,MATCH($A132-7,$A$25:$A132,1))<>0,$A132-INDEX($A$25:$A132,MATCH($A132-7,$A$25:$A132,1))<=10),B132-INDEX($B$25:$B132,MATCH($A132-7,$A$25:$A132,1)),""),"") | I132: =IFERROR(IF(AND(ISNUMBER(B132),INDEX($B$25:$B132,MATCH($A132-30,$A$25:$A132,1))<>0,INDEX($A$25:$A132,MATCH($A132-30,$A$25:$A132,1))<>0,$A132-INDEX($A$25:$A132,MATCH($A132-30,$A$25:$A132,1))<=33),B132-INDEX($B$25:$B132,MATCH($A132-30,$A$25:$A132,1)),""),"") | J132: =DATE(2026,11,3)-A132 | K132: 24 Apr
A133: 46137 | B133: 0.725 | C133: 0.28 | D133: =IF(COUNT(B133:C133)=2,B133+C133,"") | E133: =IF(ISNUMBER(B133),IFERROR(B133/$D133,""),"") | F133: =IF(ISNUMBER(C133),IFERROR(C133/$D133,""),"") | G133: =IF(COUNT(B133:C133)=2,B133-C133,"") | H133: =IFERROR(IF(AND(ISNUMBER(B133),INDEX($B$25:$B133,MATCH($A133-7,$A$25:$A133,1))<>0,INDEX($A$25:$A133,MATCH($A133-7,$A$25:$A133,1))<>0,$A133-INDEX($A$25:$A133,MATCH($A133-7,$A$25:$A133,1))<=10),B133-INDEX($B$25:$B133,MATCH($A133-7,$A$25:$A133,1)),""),"") | I133: =IFERROR(IF(AND(ISNUMBER(B133),INDEX($B$25:$B133,MATCH($A133-30,$A$25:$A133,1))<>0,INDEX($A$25:$A133,MATCH($A133-30,$A$25:$A133,1))<>0,$A133-INDEX($A$25:$A133,MATCH($A133-30,$A$25:$A133,1))<=33),B133-INDEX($B$25:$B133,MATCH($A133-30,$A$25:$A133,1)),""),"") | J133: =DATE(2026,11,3)-A133 | K133: 25 Apr
A134: 46138 | B134: 0.705 | C134: 0.28 | D134: =IF(COUNT(B134:C134)=2,B134+C134,"") | E134: =IF(ISNUMBER(B134),IFERROR(B134/$D134,""),"") | F134: =IF(ISNUMBER(C134),IFERROR(C134/$D134,""),"") | G134: =IF(COUNT(B134:C134)=2,B134-C134,"") | H134: =IFERROR(IF(AND(ISNUMBER(B134),INDEX($B$25:$B134,MATCH($A134-7,$A$25:$A134,1))<>0,INDEX($A$25:$A134,MATCH($A134-7,$A$25:$A134,1))<>0,$A134-INDEX($A$25:$A134,MATCH($A134-7,$A$25:$A134,1))<=10),B134-INDEX($B$25:$B134,MATCH($A134-7,$A$25:$A134,1)),""),"") | I134: =IFERROR(IF(AND(ISNUMBER(B134),INDEX($B$25:$B134,MATCH($A134-30,$A$25:$A134,1))<>0,INDEX($A$25:$A134,MATCH($A134-30,$A$25:$A134,1))<>0,$A134-INDEX($A$25:$A134,MATCH($A134-30,$A$25:$A134,1))<=33),B134-INDEX($B$25:$B134,MATCH($A134-30,$A$25:$A134,1)),""),"") | J134: =DATE(2026,11,3)-A134 | K134: 26 Apr
...

Sheet Kalshi
A1: Kalshi — PA-07 House Race Winner (HOUSEPA7-26)
A2: Source: Kalshi Trade API v2 (api.elections.kalshi.com), RSA-signed requests. Prices are per-$1 contracts; price = implied probability. Pulled 2026-10-12 02:24 UTC.
A4: MARKET METADATA
A5: Field | B5: Democratic (YES) | C5: Republican (YES)
A6: Market ticker | B6: HOUSEPA7-26-D | C6: HOUSEPA7-26-R
A7: Event ticker | B7: HOUSEPA7-26 | C7: HOUSEPA7-26
A8: Question | B8: Will Democratic win the House race for PA-7? | C8: Will Republican win the House race for PA-7?
A9: Candidate | B9: Bob Brooks | C9: Ryan Mackenzie
A10: Status | B10: active | C10: active
A11: Opened | B11: 2025-07-01 | C11: 2025-07-01
A12: Close time | B12: 2027-11-03 | C12: 2027-11-03
A13: Candlesticks pulled | B13: 442 | C13: 429
A15: LIVE ORDER BOOK SNAPSHOT
A16: Outcome | B16: YES Best Bid | C16: NO Best Bid | D16: YES Best Ask (1−NO bid) | E16: Mid | F16: Bid-Ask Spread | G16: YES Bid Size ($) | H16: Implied Prob (normalised)
A17: Democratic — Bob Brooks | B17: 0.86 | C17: 0.13 | D17: =1-C17 | E17: =(B17+D17)/2 | F17: =D17-B17 | G17: 14 | H17: =IFERROR(E17/$E$19,"")
A18: Republican — Ryan Mackenzie | B18: 0.12 | C18: 0.86 | D18: =1-C18 | E18: =(B18+D18)/2 | F18: =D18-B18 | G18: 10080 | H18: =IFERROR(E18/$E$19,"")
A19: Sum of mids (100% = no vig) | E19: =SUM(E17:E18) | F19: =E19-1 | H19: =SUM(H17:H18)
A21: ORDER BOOK DEPTH (top 5 levels each side)
A22: Level | B22: Dem YES Bid | C22: Dem YES Size ($) | D22: Dem NO Bid | E22: Dem NO Size ($) | F22: Rep YES Bid | G22: Rep YES Size ($) | H22: Rep NO Bid | I22: Rep NO Size ($)
A23: 1 | B23: 0.86 | C23: 14 | D23: 0.13 | E23: 99.89 | F23: 0.12 | G23: 10080 | H23: 0.86 | I23: 50065.28
A24: 2 | B24: 0.85 | C24: 50065.32 | D24: 0.12 | E24: 10560 | F24: 0.11 | G24: 539 | H24: 0.85 | I24: 10
A25: 3 | B25: 0.84 | C25: 1171.55 | D25: 0.11 | E25: 50478.69 | F25: 0.1 | G25: 50400 | H25: 0.84 | I25: 1415
A26: 4 | B26: 0.83 | C26: 73.93 | D26: 0.1 | E26: 79 | F26: 0.09 | G26: 1000 | H26: 0.83 | I26: 5107
A27: 5 | B27: 0.82 | C27: 15268 | D27: 0.091 | E27: 50 | F27: 0.075 | G27: 5000 | H27: 0.82 | I27: 10050
A29: DAILY PRICE HISTORY (1-day candlesticks)
A30: Date | B30: Dem YES Bid | C30: Dem YES Ask | D30: Dem Mid | E30: Rep YES Bid | F30: Rep YES Ask | G30: Rep Mid | H30: Sum of Mids | I30: Dem Normalised | J30: Dem − Rep Spread | K30: Volume (contracts) | L30: Open Interest | M30: Axis label
A31: 45840 | B31: 0.61 | C31: 0.66 | D31: =IF(COUNT(B31:C31)=2,(B31+C31)/2,"") | E31: 0.3 | F31: 0.35 | G31: =IF(COUNT(E31:F31)=2,(E31+F31)/2,"") | H31: =IF(AND(ISNUMBER(D31),ISNUMBER(G31)),D31+G31,"") | I31: =IFERROR(D31/H31,"") | J31: =IF(AND(ISNUMBER(D31),ISNUMBER(G31)),D31-G31,"") | K31: 0 | L31: 0 | M31: 02 Jul
A32: 45841 | B32: 0.61 | C32: 0.66 | D32: =IF(COUNT(B32:C32)=2,(B32+C32)/2,"") | E32: 0.3 | F32: 0.35 | G32: =IF(COUNT(E32:F32)=2,(E32+F32)/2,"") | H32: =IF(AND(ISNUMBER(D32),ISNUMBER(G32)),D32+G32,"") | I32: =IFERROR(D32/H32,"") | J32: =IF(AND(ISNUMBER(D32),ISNUMBER(G32)),D32-G32,"") | K32: 0 | L32: 0 | M32: 03 Jul
A33: 45842 | B33: 0.61 | C33: 0.66 | D33: =IF(COUNT(B33:C33)=2,(B33+C33)/2,"") | E33: 0.3 | F33: 0.35 | G33: =IF(COUNT(E33:F33)=2,(E33+F33)/2,"") | H33: =IF(AND(ISNUMBER(D33),ISNUMBER(G33)),D33+G33,"") | I33: =IFERROR(D33/H33,"") | J33: =IF(AND(ISNUMBER(D33),ISNUMBER(G33)),D33-G33,"") | K33: 0 | L33: 0 | M33: 04 Jul
A34: 45843 | B34: 0.61 | C34: 0.66 | D34: =IF(COUNT(B34:C34)=2,(B34+C34)/2,"") | E34: 0.3 | F34: 0.35 | G34: =IF(COUNT(E34:F34)=2,(E34+F34)/2,"") | H34: =IF(AND(ISNUMBER(D34),ISNUMBER(G34)),D34+G34,"") | I34: =IFERROR(D34/H34,"") | J34: =IF(AND(ISNUMBER(D34),ISNUMBER(G34)),D34-G34,"") | K34: 0 | L34: 0 | M34: 05 Jul
A35: 45844 | B35: 0.61 | C35: 0.66 | D35: =IF(COUNT(B35:C35)=2,(B35+C35)/2,"") | E35: 0.31 | F35: 0.36 | G35: =IF(COUNT(E35:F35)=2,(E35+F35)/2,"") | H35: =IF(AND(ISNUMBER(D35),ISNUMBER(G35)),D35+G35,"") | I35: =IFERROR(D35/H35,"") | J35: =IF(AND(ISNUMBER(D35),ISNUMBER(G35)),D35-G35,"") | K35: 298 | L35: 152 | M35: 06 Jul
A36: 45845 | B36: 0.61 | C36: 0.66 | D36: =IF(COUNT(B36:C36)=2,(B36+C36)/2,"") | E36: 0.31 | F36: 0.36 | G36: =IF(COUNT(E36:F36)=2,(E36+F36)/2,"") | H36: =IF(AND(ISNUMBER(D36),ISNUMBER(G36)),D36+G36,"") | I36: =IFERROR(D36/H36,"") | J36: =IF(AND(ISNUMBER(D36),ISNUMBER(G36)),D36-G36,"") | K36: 0 | L36: 152 | M36: 07 Jul
A37: 45846 | B37: 0.61 | C37: 0.66 | D37: =IF(COUNT(B37:C37)=2,(B37+C37)/2,"") | E37: 0.31 | F37: 0.36 | G37: =IF(COUNT(E37:F37)=2,(E37+F37)/2,"") | H37: =IF(AND(ISNUMBER(D37),ISNUMBER(G37)),D37+G37,"") | I37: =IFERROR(D37/H37,"") | J37: =IF(AND(ISNUMBER(D37),ISNUMBER(G37)),D37-G37,"") | K37: 0 | L37: 152 | M37: 08 Jul
A38: 45847 | B38: 0.61 | C38: 0.66 | D38: =IF(COUNT(B38:C38)=2,(B38+C38)/2,"") | E38: 0.31 | F38: 0.36 | G38: =IF(COUNT(E38:F38)=2,(E38+F38)/2,"") | H38: =IF(AND(ISNUMBER(D38),ISNUMBER(G38)),D38+G38,"") | I38: =IFERROR(D38/H38,"") | J38: =IF(AND(ISNUMBER(D38),ISNUMBER(G38)),D38-G38,"") | K38: 0 | L38: 152 | M38: 09 Jul
A39: 45848 | B39: 0.61 | C39: 0.66 | D39: =IF(COUNT(B39:C39)=2,(B39+C39)/2,"") | E39: 0.31 | F39: 0.36 | G39: =IF(COUNT(E39:F39)=2,(E39+F39)/2,"") | H39: =IF(AND(ISNUMBER(D39),ISNUMBER(G39)),D39+G39,"") | I39: =IFERROR(D39/H39,"") | J39: =IF(AND(ISNUMBER(D39),ISNUMBER(G39)),D39-G39,"") | K39: 0 | L39: 152 | M39: 10 Jul
A40: 45849 | B40: 0.61 | C40: 0.66 | D40: =IF(COUNT(B40:C40)=2,(B40+C40)/2,"") | E40: 0.31 | F40: 0.36 | G40: =IF(COUNT(E40:F40)=2,(E40+F40)/2,"") | H40: =IF(AND(ISNUMBER(D40),ISNUMBER(G40)),D40+G40,"") | I40: =IFERROR(D40/H40,"") | J40: =IF(AND(ISNUMBER(D40),ISNUMBER(G40)),D40-G40,"") | K40: 0 | L40: 152 | M40: 11 Jul
A41: 45850 | B41: 0.61 | C41: 0.66 | D41: =IF(COUNT(B41:C41)=2,(B41+C41)/2,"") | E41: 0.31 | F41: 0.36 | G41: =IF(COUNT(E41:F41)=2,(E41+F41)/2,"") | H41: =IF(AND(ISNUMBER(D41),ISNUMBER(G41)),D41+G41,"") | I41: =IFERROR(D41/H41,"") | J41: =IF(AND(ISNUMBER(D41),ISNUMBER(G41)),D41-G41,"") | K41: 0 | L41: 152 | M41: 12 Jul
A42: 45851 | B42: 0.61 | C42: 0.66 | D42: =IF(COUNT(B42:C42)=2,(B42+C42)/2,"") | E42: 0.31 | F42: 0.36 | G42: =IF(COUNT(E42:F42)=2,(E42+F42)/2,"") | H42: =IF(AND(ISNUMBER(D42),ISNUMBER(G42)),D42+G42,"") | I42: =IFERROR(D42/H42,"") | J42: =IF(AND(ISNUMBER(D42),ISNUMBER(G42)),D42-G42,"") | K42: 0 | L42: 152 | M42: 13 Jul
... A267: 46076 | B267: 0.7 | C267: 0.74 | D267: =IF(COUNT(B267:C267)=2,(B267+C267)/2,"") | E267: 0.22 | F267: 0.26 | G267: =IF(COUNT(E267:F267)=2,(E267+F267)/2,"") | H267: =IF(AND(ISNUMBER(D267),ISNUMBER(G267)),D267+G267,"") | I267: =IFERROR(D267/H267,"") | J267: =IF(AND(ISNUMBER(D267),ISNUMBER(G267)),D267-G267,"") | K267: 0 | L267: 6710 | M267: 23 Feb
A268: 46077 | B268: 0.7 | C268: 0.74 | D268: =IF(COUNT(B268:C268)=2,(B268+C268)/2,"") | G268: =IF(COUNT(E268:F268)=2,(E268+F268)/2,"") | H268: =IF(AND(ISNUMBER(D268),ISNUMBER(G268)),D268+G268,"") | I268: =IFERROR(D268/H268,"") | J268: =IF(AND(ISNUMBER(D268),ISNUMBER(G268)),D268-G268,"") | K268: 0 | L268: 6710 | M268: 24 Feb
...

Sheet Margin of Victory
A1: Margin of Victory — PA-07 (Polymarket)
A2: The PA-07 winning margin, quoted on BOTH venues: Polymarket as exclusive brackets (below) and Kalshi as nested thresholds (further down, with the two compared). Pulled 2026-10-12 02:24 UTC.
A4: MARKET METADATA
A5: Event | B5: PA-07 House Election Margin of Victory
A6: Slug | B6: pa-07-house-margin-of-victory-2026
A7: Event id | B7: 834502
A8: Opened | B8: 2026-08-11
A9: Resolution date | B9: 2026-11-04
A10: Volume ($) | B10: 15737.082
A11: Liquidity ($) | B11: 162275.8
A12: Brackets listed | B12: 10
A14: LIVE BRACKET LADDER
A15: Bracket | B15: Signed Midpoint (pts) | C15: Best Bid | D15: Best Ask | E15: Mid | F15: Normalised Prob | G15: Cumulative | H15: Volume ($) | I15: Liquidity ($) | J15: Prob × Midpoint
A16: Republican 6%+ | B16: -8 | C16: 0.016 | D16: 0.078 | E16: =IF(COUNT(C16:D16)=2,(C16+D16)/2,"") | F16: =IFERROR(E16/$E$26,"") | G16: =IFERROR(SUM($F$16:F16),"") | H16: 1219.8912 | I16: 20139.616 | J16: =IFERROR(F16*B16,"")
A17: Republican 3-6% | B17: -4.5 | C17: 0.04 | D17: 0.041 | E17: =IF(COUNT(C17:D17)=2,(C17+D17)/2,"") | F17: =IFERROR(E17/$E$26,"") | G17: =IFERROR(SUM($F$16:F17),"") | H17: 934.03986 | I17: 20510.613 | J17: =IFERROR(F17*B17,"")
A18: Republican 0-3% | B18: -1.5 | C18: 0.09 | D18: 0.1 | E18: =IF(COUNT(C18:D18)=2,(C18+D18)/2,"") | F18: =IFERROR(E18/$E$26,"") | G18: =IFERROR(SUM($F$16:F18),"") | H18: 816.67293 | I18: 18363.776 | J18: =IFERROR(F18*B18,"")
A19: Democrat 0-3% | B19: 1.5 | C19: 0.11 | D19: 0.13 | E19: =IF(COUNT(C19:D19)=2,(C19+D19)/2,"") | F19: =IFERROR(E19/$E$26,"") | G19: =IFERROR(SUM($F$16:F19),"") | H19: 4100.8265 | I19: 20514.047 | J19: =IFERROR(F19*B19,"")
A20: Democrat 3-6% | B20: 4.5 | C20: 0.27 | D20: 0.28 | E20: =IF(COUNT(C20:D20)=2,(C20+D20)/2,"") | F20: =IFERROR(E20/$E$26,"") | G20: =IFERROR(SUM($F$16:F20),"") | H20: 2122.9772 | I20: 20684.719 | J20: =IFERROR(F20*B20,"")
A21: Democrat 6-9% | B21: 7.5 | C21: 0.167 | D21: 0.177 | E21: =IF(COUNT(C21:D21)=2,(C21+D21)/2,"") | F21: =IFERROR(E21/$E$26,"") | G21: =IFERROR(SUM($F$16:F21),"") | H21: 2661.0342 | I21: 19229.334 | J21: =IFERROR(F21*B21,"")
A22: Democrat 9-12% | B22: 10.5 | C22: 0.014 | D22: 0.207 | E22: =IF(COUNT(C22:D22)=2,(C22+D22)/2,"") | F22: =IFERROR(E22/$E$26,"") | G22: =IFERROR(SUM($F$16:F22),"") | H22: 986.28736 | I22: 10644.012 | J22: =IFERROR(F22*B22,"")
A23: Democrat 12-15% | B23: 13.5 | C23: 0.04 | D23: 0.08 | E23: =IF(COUNT(C23:D23)=2,(C23+D23)/2,"") | F23: =IFERROR(E23/$E$26,"") | G23: =IFERROR(SUM($F$16:F23),"") | H23: 1014.9916 | I23: 11808.655 | J23: =IFERROR(F23*B23,"")
A24: Democrat 15-18% | B24: 16.5 | C24: 0.016 | D24: 0.25 | E24: =IF(COUNT(C24:D24)=2,(C24+D24)/2,"") | F24: =IFERROR(E24/$E$26,"") | G24: =IFERROR(SUM($F$16:F24),"") | H24: 813.45533 | I24: 520.95803 | J24: =IFERROR(F24*B24,"")
A25: Democrat 18%+ | B25: 20 | C25: 0.031 | D25: 0.044 | E25: =IF(COUNT(C25:D25)=2,(C25+D25)/2,"") | F25: =IFERROR(E25/$E$26,"") | G25: =IFERROR(SUM($F$16:F25),"") | H25: 1066.9056 | I25: 19972.951 | J25: =IFERROR(F25*B25,"")
A26: TOTAL | E26: =SUM(E16:E25) | F26: =SUM(F16:F25) | H26: =SUM(H16:H25) | I26: =SUM(I16:I25) | J26: =SUM(J16:J25)
A28: IMPLIED DISTRIBUTION
A29: P(Democrat wins) — from ladder | B29: =IFERROR(SUMIF($A$16:$A$25,"Democrat*",$F$16:$F$25),"")
A30: P(Republican wins) — from ladder | B30: =IFERROR(SUMIF($A$16:$A$25,"Republican*",$F$16:$F$25),"")
A31: Expected margin (D−R) | B31: =IFERROR(SUM(J16:J25),"")
A32: P(margin under 3 pts either way) | B32: =IFERROR(SUMIFS($F$16:$F$25,$B$16:$B$25,">-3",$B$16:$B$25,"<3"),"")
A33: P(margin under 6 pts either way) | B33: =IFERROR(SUMIFS($F$16:$F$25,$B$16:$B$25,">-6",$B$16:$B$25,"<6"),"")
A35: CROSS-CHECK vs THE WINNER MARKET
A36: Winner market — Polymarket Dem mid | B36: =Polymarket!D19
A37: Margin ladder — P(Democrat wins) | B37: =B29
A38: Discrepancy (ladder − winner) | B38: =IFERROR(B29-B36,"")
A39: Both markets describe the same event on the same venue, so a large gap is a sign the thin margin ladder is mispriced rather than a signal about the race. The winner market carries far more volume; trust it first.
A41: DAILY BRACKET HISTORY
A42: Date | B42: Republican 6%+ | C42: Republican 3-6% | D42: Republican 0-3% | E42: Democrat 0-3% | F42: Democrat 3-6% | G42: Democrat 6-9% | H42: Democrat 9-12% | I42: Democrat 12-15% | J42: Democrat 15-18% | K42: Democrat 18%+
A43: 46246 | B43: 0.365 | C43: 0.365 | D43: 0.365 | E43: 0.365 | F43: 0.365 | G43: 0.365 | H43: 0.365 | I43: 0.365 | J43: 0.365 | K43: 0.365
A44: 46247 | B44: 0.365 | C44: 0.365 | D44: 0.365 | E44: 0.365 | F44: 0.365 | G44: 0.365 | H44: 0.365 | I44: 0.365 | J44: 0.365 | K44: 0.365
A45: 46248 | B45: 0.37 | C45: 0.37 | D45: 0.37 | E45: 0.37 | F45: 0.365 | G45: 0.365 | H45: 0.37 | I45: 0.37 | J45: 0.37 | K45: 0.37
...

Sheet Voter Turnout
A1: Voter Turnout — PA-07 (Kalshi)
A2: Kalshi KXMIDTERMVOTETURN-PA07: how many ballots the PA-07 House race draws on 3 Nov 2026, quoted as thresholds. Pulled 2026-10-12 02:24 UTC.
A4: MARKET METADATA
A5: Event | B5: KXMIDTERMVOTETURN-PA07
A6: Series | B6: KXMIDTERMVOTETURN
A7: Question | B7: Pennsylvania 07 House General Election: voter turnout
A8: Resolution | B8: 3 Nov 2026
A9: Thresholds quoted | B9: 8
A11: THRESHOLD LADDER
A12: Rung | B12: Threshold | C12: YES Bid | D12: YES Ask | E12: Mid P(turnout ≥ strike) | F12: Bucket | G12: Bucket Prob | H12: Representative Turnout | I12: Prob × Turnout
A13: Below 220K | F13: under 220K | G13: =IFERROR(MAX(0,1-E14),"") | H13: 295000 | I13: =IFERROR(G13*H13,"")
A14: Above 220K | B14: 220000 | C14: 0.94 | D14: 0.99 | E14: =IF(COUNT(C14:D14)=2,(C14+D14)/2,"") | F14: 220K–260K | G14: =IFERROR(MAX(0,E14-E15),"") | H14: 240000 | I14: =IFERROR(G14*H14,"")
A15: Above 260K | B15: 260000 | C15: 0.78 | D15: 0.87 | E15: =IF(COUNT(C15:D15)=2,(C15+D15)/2,"") | F15: 260K–280K | G15: =IFERROR(MAX(0,E15-E16),"") | H15: 270000 | I15: =IFERROR(G15*H15,"")
A16: Above 280K | B16: 280000 | C16: 0.64 | D16: 0.73 | E16: =IF(COUNT(C16:D16)=2,(C16+D16)/2,"") | F16: 280K–310K | G16: =IFERROR(MAX(0,E16-E17),"") | H16: 295000 | I16: =IFERROR(G16*H16,"")
A17: Above 310K | B17: 310000 | C17: 0.37 | D17: 0.46 | E17: =IF(COUNT(C17:D17)=2,(C17+D17)/2,"") | F17: 310K–320K | G17: =IFERROR(MAX(0,E17-E18),"") | H17: 315000 | I17: =IFERROR(G17*H17,"")
A18: Above 320K | B18: 320000 | C18: 0.32 | D18: 0.39 | E18: =IF(COUNT(C18:D18)=2,(C18+D18)/2,"") | F18: 320K–340K | G18: =IFERROR(MAX(0,E18-E19),"") | H18: 330000 | I18: =IFERROR(G18*H18,"")
A19: Above 340K | B19: 340000 | C19: 0.19 | D19: 0.28 | E19: =IF(COUNT(C19:D19)=2,(C19+D19)/2,"") | F19: 340K–360K | G19: =IFERROR(MAX(0,E19-E20),"") | H19: 350000 | I19: =IFERROR(G19*H19,"")
A20: Above 360K | B20: 360000 | C20: 0.11 | D20: 0.2 | E20: =IF(COUNT(C20:D20)=2,(C20+D20)/2,"") | F20: 360K–370K | G20: =IFERROR(MAX(0,E20-E21),"") | H20: 365000 | I20: =IFERROR(G20*H20,"")
A21: Above 370K | B21: 370000 | C21: 0.1 | D21: 0.17 | E21: =IF(COUNT(C21:D21)=2,(C21+D21)/2,"") | F21: above 370K | G21: =IFERROR(E21,"") | H21: 385000 | I21: =IFERROR(G21*H21,"")
A22: TOTAL | G22: =SUM(G13:G21) | I22: =SUM(I13:I21)
A24: IMPLIED READ
A25: Expected turnout | B25: =IFERROR(SUM(I13:I21),"")
A26: Modal bucket | B26: =IFERROR(INDEX($F$13:$F$21,MATCH(MAX($G$13:$G$21),$G$13:$G$21,0)),"")
A27: P(turnout above 340K) | B27: =IFERROR(INDEX($E$13:$E$21,MATCH(340000,$B$13:$B$21,0)),"")
A28: 2024 PA-07 House turnout | B28: 403314
A29: Implied change vs 2024 | B29: =IFERROR(B25/B28-1,"")
A30: Turnout is a genuine driver here, not trivia: PA-07 was decided by about a point in 2024, so which electorate shows up plausibly decides the seat.
A32: DAILY HISTORY (mid of closing bid and ask)
A33: Date | B33: Above 220K | C33: Above 260K | D33: Above 280K | E33: Above 310K | F33: Above 320K | G33: Above 340K | H33: Above 360K | I33: Above 370K
A34: 46150 | E34: 0.75 | F34: 0.63 | G34: 0.5 | H34: 0.375 | I34: 0.25
A35: 46156 | F35: 0.63 | G35: 0.5 | H35: 0.375 | I35: 0.25
A36: 46161 | F36: 0.63 | G36: 0.5 | H36: 0.375 | I36: 0.25
A37: 46164 | E37: 0.575 | F37: 0.63 | G37: 0.5 | H37: 0.375 | I37: 0.25
A38: 46165 | E38: 0.75 | F38: 0.63 | G38: 0.5 | H38: 0.375 | I38: 0.25
A39: 46170 | F39: 0.625 | H39: 0.375
A40: 46175 | E40: 0.75
A41: 46177 | F41: 0.625
A42: 46180 | E42: 0.75 | H42: 0.375 | I42: 0.25
A43: 46181 | E43: 0.75 | H43: 0.375 | I43: 0.25
A44: 46182 | E44: 0.75 | H44: 0.375 | I44: 0.25
...

Sheet PA Seat Count
A1: PA Democratic House Seats — Kalshi (KXHOUSEWINSTATE-PAD)
A2: How many of Pennsylvania's 17 House seats Democrats win on 3 Nov 2026. PA-07 is one of the seats in this count, so the ladder is a state-level read on the same question. Pulled 2026-10-12 02:24 UTC.
A4: MARKET METADATA
A5: Event | B5: KXHOUSEWINSTATE-PAD
A6: Question | B6: How many House seats will Democrats win in Pennsylvania?
A7: Resolution | B7: On Nov 3, 2026
A8: Series | B8: KXHOUSEWINSTATE
A9: Brackets listed | B9: 8
A11: LIVE BRACKET LADDER
A12: Bracket | B12: Seats (assumed) | C12: YES Bid | D12: NO Bid | E12: YES Ask | F12: Mid | G12: Normalised Prob | H12: Cumulative | I12: Prob × Seats
A13: Below 7 | B13: 6 | D13: 0.99 | E13: =IF(ISNUMBER(D13),1-D13,"") | F13: =IF(COUNT(C13,E13)=2,(C13+E13)/2,IF(ISNUMBER(E13),E13/2,"")) | G13: =IFERROR(F13/$F$21,"") | H13: =IFERROR(SUM($G$13:G13),"") | I13: =IFERROR(G13*B13,"")
A14: 7 | B14: 7 | C14: 0.02 | D14: 0.94 | E14: =IF(ISNUMBER(D14),1-D14,"") | F14: =IF(COUNT(C14,E14)=2,(C14+E14)/2,IF(ISNUMBER(E14),E14/2,"")) | G14: =IFERROR(F14/$F$21,"") | H14: =IFERROR(SUM($G$13:G14),"") | I14: =IFERROR(G14*B14,"")
A15: 8 | B15: 8 | C15: 0.03 | D15: 0.91 | E15: =IF(ISNUMBER(D15),1-D15,"") | F15: =IF(COUNT(C15,E15)=2,(C15+E15)/2,IF(ISNUMBER(E15),E15/2,"")) | G15: =IFERROR(F15/$F$21,"") | H15: =IFERROR(SUM($G$13:G15),"") | I15: =IFERROR(G15*B15,"")
A16: 9 | B16: 9 | C16: 0.19 | D16: 0.78 | E16: =IF(ISNUMBER(D16),1-D16,"") | F16: =IF(COUNT(C16,E16)=2,(C16+E16)/2,IF(ISNUMBER(E16),E16/2,"")) | G16: =IFERROR(F16/$F$21,"") | H16: =IFERROR(SUM($G$13:G16),"") | I16: =IFERROR(G16*B16,"")
A17: 10 | B17: 10 | C17: 0.21 | D17: 0.76 | E17: =IF(ISNUMBER(D17),1-D17,"") | F17: =IF(COUNT(C17,E17)=2,(C17+E17)/2,IF(ISNUMBER(E17),E17/2,"")) | G17: =IFERROR(F17/$F$21,"") | H17: =IFERROR(SUM($G$13:G17),"") | I17: =IFERROR(G17*B17,"")
A18: 11 | B18: 11 | C18: 0.38 | D18: 0.58 | E18: =IF(ISNUMBER(D18),1-D18,"") | F18: =IF(COUNT(C18,E18)=2,(C18+E18)/2,IF(ISNUMBER(E18),E18/2,"")) | G18: =IFERROR(F18/$F$21,"") | H18: =IFERROR(SUM($G$13:G18),"") | I18: =IFERROR(G18*B18,"")
A19: 12 | B19: 12 | C19: 0.02 | D19: 0.96 | E19: =IF(ISNUMBER(D19),1-D19,"") | F19: =IF(COUNT(C19,E19)=2,(C19+E19)/2,IF(ISNUMBER(E19),E19/2,"")) | G19: =IFERROR(F19/$F$21,"") | H19: =IFERROR(SUM($G$13:G19),"") | I19: =IFERROR(G19*B19,"")
A20: Above 12 | B20: 13 | C20: 0.02 | D20: 0.95 | E20: =IF(ISNUMBER(D20),1-D20,"") | F20: =IF(COUNT(C20,E20)=2,(C20+E20)/2,IF(ISNUMBER(E20),E20/2,"")) | G20: =IFERROR(F20/$F$21,"") | H20: =IFERROR(SUM($G$13:G20),"") | I20: =IFERROR(G20*B20,"")
A21: TOTAL | F21: =SUM(F13:F20) | G21: =SUM(G13:G20) | I21: =SUM(I13:I20)
A23: IMPLIED READ
A24: Expected Democratic seats | B24: =IFERROR(SUM(I13:I20),"")
A25: Modal bracket | B25: =IFERROR(INDEX($A$13:$A$20,MATCH(MAX($G$13:$G$20),$G$13:$G$20,0)),"")
A26: P(9 or more seats) | B26: =IFERROR(SUMIF($B$13:$B$20,">=9",$G$13:$G$20),"")
A27: PA seats held by Democrats now | B27: 8
A28: Implied net gain | B28: =IFERROR(B24-B27,"")
A29: PA's delegation is 17 seats. The 8-seat current baseline is entered by hand as the Democratic count going into the 2026 cycle — check it against the current delegation before relying on the net-gain line. A market expectation above that baseline is consistent with Democrats favoured to flip PA-07.
A31: DAILY BRACKET HISTORY (mid of YES bid and derived ask)
A32: Date | B32: Below 7 | C32: 7 | D32: 8 | E32: 9 | F32: 10 | G32: 11 | H32: 12 | I32: Above 12
A33: 46254 | B33: 0.015 | C33: 0.025 | D33: 0.13 | E33: 0.405 | F33: 0.295 | G33: 0.145 | H33: 0.025 | I33: 0.015
A34: 46255 | B34: 0.015 | C34: 0.025 | D34: 0.125 | E34: 0.355 | F34: 0.295 | G34: 0.215 | H34: 0.015 | I34: 0.015
A35: 46256 | B35: 0.015 | C35: 0.035 | D35: 0.125 | E35: 0.355 | F35: 0.295 | G35: 0.23 | H35: 0.015 | I35: 0.015
A36: 46257 | B36: 0.005 | C36: 0.04 | D36: 0.085 | E36: 0.3 | F36: 0.26 | G36: 0.26 | H36: 0.015 | I36: 0.01
A37: 46258 | B37: 0.005 | C37: 0.045 | D37: 0.065 | E37: 0.285 | F37: 0.235 | G37: 0.255 | H37: 0.035 | I37: 0.01
A38: 46259 | C38: 0.045 | D38: 0.06 | E38: 0.305 | F38: 0.235 | G38: 0.255 | H38: 0.035
A39: 46260 | C39: 0.04 | E39: 0.31 | F39: 0.235 | G39: 0.255 | H39: 0.035 | I39: 0.005
A40: 46261 | B40: 0.005 | C40: 0.045 | D40: 0.055 | E40: 0.31 | F40: 0.185 | G40: 0.27 | H40: 0.035 | I40: 0.01
A41: 46262 | C41: 0.045 | D41: 0.04 | E41: 0.3 | F41: 0.185 | G41: 0.325 | H41: 0.045
A42: 46263 | C42: 0.045 | D42: 0.035 | E42: 0.32 | F42: 0.195 | G42: 0.33 | H42: 0.055
A43: 46264 | C43: 0.045 | D43: 0.05 | E43: 0.33 | F43: 0.19 | G43: 0.335 | H43: 0.05
A44: 46265 | B44: 0.005 | C44: 0.05 | D44: 0.055 | E44: 0.325 | F44: 0.175 | G44: 0.34 | H44: 0.035
...

Sheet Polls
A1: Polls — PA-07
A2: General-election and Democratic-primary polling for Pennsylvania's 7th, from the NYT/538 house-poll file (house.csv), plus the district and incumbent profile from GovTrack. Percentages stored as fractions. Compiled 2026-10-12 02:24 UTC.
A4: HOW TO USE THIS SHEET
A5: • Add a general-election poll by typing into the next blank blue row of the log below — rows are pre-formulated to row 28, so columns L to O fill themselves.
A6: • Percentages are percent-formatted, so type 47% (not 47). Sponsor Lean must be D, R or None.
A7: • The three yellow cells in POLLING AVERAGE drive the weighting. Change them and everything downstream updates.
A8: • A greyed EXAMPLE row at the bottom shows the expected format. It sits outside every averaged range and can be deleted.
A10: GENERAL ELECTION POLL LOG — Brooks (D) vs Mackenzie (R)
A11: Pollster | B11: Sponsor / Client | C11: Sponsor Lean | D11: Field Start | E11: Field End | F11: Sample | G11: Pop. | H11: MoE | I11: Brooks (D) | J11: Mackenzie (R) | K11: Other / Undecided | L11: Margin (D−R) | M11: Days Ago | N11: Recency Weight | O11: Poll Weight
A12: GBAO | B12: House Majority PAC | C12: D | D12: 46202 | E12: 46205 | F12: 550 | G12: LV | I12: 0.47 | J12: 0.43 | L12: =IF(COUNT(I12:J12)=2,I12-J12,"") | M12: =IF(ISNUMBER(E12),$B$28-E12,"") | N12: =IF(ISNUMBER(M12),0.5^(M12/$B$29),"") | O12: =IF(AND(ISNUMBER(F12),ISNUMBER(N12)),F12*N12,"")
L13: =IF(COUNT(I13:J13)=2,I13-J13,"") | M13: =IF(ISNUMBER(E13),$B$28-E13,"") | N13: =IF(ISNUMBER(M13),0.5^(M13/$B$29),"") | O13: =IF(AND(ISNUMBER(F13),ISNUMBER(N13)),F13*N13,"")
L14: =IF(COUNT(I14:J14)=2,I14-J14,"") | M14: =IF(ISNUMBER(E14),$B$28-E14,"") | N14: =IF(ISNUMBER(M14),0.5^(M14/$B$29),"") | O14: =IF(AND(ISNUMBER(F14),ISNUMBER(N14)),F14*N14,"")
L15: =IF(COUNT(I15:J15)=2,I15-J15,"") | M15: =IF(ISNUMBER(E15),$B$28-E15,"") | N15: =IF(ISNUMBER(M15),0.5^(M15/$B$29),"") | O15: =IF(AND(ISNUMBER(F15),ISNUMBER(N15)),F15*N15,"")
L16: =IF(COUNT(I16:J16)=2,I16-J16,"") | M16: =IF(ISNUMBER(E16),$B$28-E16,"") | N16: =IF(ISNUMBER(M16),0.5^(M16/$B$29),"") | O16: =IF(AND(ISNUMBER(F16),ISNUMBER(N16)),F16*N16,"")
L17: =IF(COUNT(I17:J17)=2,I17-J17,"") | M17: =IF(ISNUMBER(E17),$B$28-E17,"") | N17: =IF(ISNUMBER(M17),0.5^(M17/$B$29),"") | O17: =IF(AND(ISNUMBER(F17),ISNUMBER(N17)),F17*N17,"")
L18: =IF(COUNT(I18:J18)=2,I18-J18,"") | M18: =IF(ISNUMBER(E18),$B$28-E18,"") | N18: =IF(ISNUMBER(M18),0.5^(M18/$B$29),"") | O18: =IF(AND(ISNUMBER(F18),ISNUMBER(N18)),F18*N18,"")
L19: =IF(COUNT(I19:J19)=2,I19-J19,"") | M19: =IF(ISNUMBER(E19),$B$28-E19,"") | N19: =IF(ISNUMBER(M19),0.5^(M19/$B$29),"") | O19: =IF(AND(ISNUMBER(F19),ISNUMBER(N19)),F19*N19,"")
L20: =IF(COUNT(I20:J20)=2,I20-J20,"") | M20: =IF(ISNUMBER(E20),$B$28-E20,"") | N20: =IF(ISNUMBER(M20),0.5^(M20/$B$29),"") | O20: =IF(AND(ISNUMBER(F20),ISNUMBER(N20)),F20*N20,"")
L21: =IF(COUNT(I21:J21)=2,I21-J21,"") | M21: =IF(ISNUMBER(E21),$B$28-E21,"") | N21: =IF(ISNUMBER(M21),0.5^(M21/$B$29),"") | O21: =IF(AND(ISNUMBER(F21),ISNUMBER(N21)),F21*N21,"")
L22: =IF(COUNT(I22:J22)=2,I22-J22,"") | M22: =IF(ISNUMBER(E22),$B$28-E22,"") | N22: =IF(ISNUMBER(M22),0.5^(M22/$B$29),"") | O22: =IF(AND(ISNUMBER(F22),ISNUMBER(N22)),F22*N22,"")
L23: =IF(COUNT(I23:J23)=2,I23-J23,"") | M23: =IF(ISNUMBER(E23),$B$28-E23,"") | N23: =IF(ISNUMBER(M23),0.5^(M23/$B$29),"") | O23: =IF(AND(ISNUMBER(F23),ISNUMBER(N23)),F23*N23,"")
L24: =IF(COUNT(I24:J24)=2,I24-J24,"") | M24: =IF(ISNUMBER(E24),$B$28-E24,"") | N24: =IF(ISNUMBER(M24),0.5^(M24/$B$29),"") | O24: =IF(AND(ISNUMBER(F24),ISNUMBER(N24)),F24*N24,"")
A25: Source: house.csv (NYT / 538 house-poll file), rows filtered to state = PA and seat_number = 7, stage = general. The pollster-rating fields (numeric_grade, pollscore, transparency_score) are empty for every PA-07 poll in that file.
A27: POLLING AVERAGE
A28: Reference date (as of) | B28: 46307
A29: Recency half-life (days) | B29: 45
A30: Partisan house-effect haircut | B30: 0.03
A32: Polls in average | B32: =COUNT(L12:L24)
A33: Weighted Brooks (D) | B33: =IFERROR(SUMPRODUCT(I12:I24,O12:O24)/SUM(O12:O24),"")
A34: Weighted Mackenzie (R) | B34: =IFERROR(SUMPRODUCT(J12:J24,O12:O24)/SUM(O12:O24),"")
A35: Weighted margin (D−R) | B35: =IFERROR(B33-B34,"")
A36: Net partisan sponsorship | B36: =IFERROR((SUMIF($C$12:$C$24,"D",$O$12:$O$24)-SUMIF($C$12:$C$24,"R",$O$12:$O$24))/SUM($O$12:$O$24),"")
A37: Adjusted margin (D−R) | B37: =IFERROR(B35-B36*B30,"")
A38: Simple (unweighted) margin | B38: =IFERROR(AVERAGE(L12:L24),"")
A39: Most recent poll date | B39: =IFERROR(MAX(E12:E24),"")
A40: Days since most recent poll | B40: =IFERROR($B$28-MAX(E12:E24),"")
A41: Only one public general-election poll exists for PA-07 so far, and it is Democratic-sponsored. The average is a single data point wearing a weighting scheme — read the adjusted margin, and lean on the market sheets.
A43: DEMOCRATIC PRIMARY POLLS (settled 19 May 2026) — for calibration
A44: Pollster | B44: Sponsor / Client | C44: Lean | D44: Field Start | E44: Field End | F44: Sample | G44: Pop. | H44: Brooks | I44: McClure | J44: Crosswell | K44: Obando-Derstine | L44: Undecided | M44: Other | N44: Brooks Lead | O44: Leader
A45: Change Research | B45: (none) | C45: None | D45: 46007 | E45: 46010 | F45: 892 | G45: LV | H45: 0.11 | I45: 0.17 | J45: 0.05 | K45: 0.1 | L45: 0.53 | M45: 0.03 | N45: =IF(COUNT(H45:K45)>1,H45-MAX(I45:K45),"") | O45: =IF(COUNT(H45:K45)=0,"",INDEX($H$44:$K$44,MATCH(MAX(H45:K45),H45:K45,0)))
...

Sheet Forecast & Aggregators
A1: Forecast & Aggregators
A2: Outside views of PA-07: a statistical forecast, a third-party odds tracker, and what each disagrees with the markets about. Compiled 2026-10-12 02:24 UTC.
A4: MODEL vs MARKET — the headline disagreement
A5: Market consensus P(Dem) | B5: =AVERAGE(Polymarket!D19,Kalshi!E17) | D5: Equal-weighted mean of the two venue mids, read directly from their APIs.
A6: PollsMax model P(Dem) | B6: 0.595 | D6: Polls plus fundamentals through a Monte Carlo, not a traded price.
A7: Gap (market − model) | B7: =IF(AND(ISNUMBER(B5),ISNUMBER(B6)),B5-B6,"")
A8: Projected margin (model) | B8: 0.6 | D8: Model's central vote-margin estimate, D positive.
A9: Rating (model)
A10: A gap this wide is the single most interesting number in this workbook: the model projects a roughly one-point race yet the markets price the Democrat far above even odds. Either the market knows something the fundamentals do not, or it is overconfident about a tossup.
A12: POLLSMAX — forecast detail
A13: Brooks (D) win probability | B13: 0.595
A14: Mackenzie (R) win probability | B14: 0.405
A15: Projected margin (D−R) | B15: 0.6
A16: Polling average — Brooks | B16: 0.47
A17: Polling average — Mackenzie | B17: 0.43
A18: Polling average margin | B18: 0.04
A19: Polls in their average | B19: 1
A20: Average as of | B20: August 30, 2026
A21: Retrieved | B21: 2026-08-30T16:21:45Z
A22: Uncertainty band: Site plots a daily Upper/Lower simulation band around both the projected vote share and the win-probability trend lines, but does not disclose what confidence/percentile level those bands represent. As of the last plotted day (2026-08-19): projected vote share Brooks 50.3% [48.49-52.12] / Mackenzie 49.7% [47.88-51.51]; win probability Brooks 59.53% [54.53-64.53] / Mackenzie 40.47% [35.47-45.47].
A24: POLLSMAX — methodology, in their words
A25: Summary | B25: Pollsmax runs two linked systems: (1) a polling-average model that produces a time-weighted, partisanship-adjusted mean of all polls for a race, and (2) a forecast model that blends that polling average with structural 'fundamentals' (generic ballot, presidential approval, incumbency, prior results, partisan lean/PVI, and Pollsmax's own editorial rating) into a composite margin, which is then run through 10,000-100,000 daily Monte Carlo simulations to produce win probabilities, a projected margin, and projected vote shares.
A26: Weighting | B26: Race-page polling averages are a recency-weighted mean of all polls dated on or before each chart day, with the recency curve adapting to how many polls exist so sparse races (like this one, with only 1 poll) do not overreact to a single survey. Forecasts blend polling with fundamentals; at full poll depth (6+ polls for House) the standardized House weights are: Polling 30%, Editorial rating 40%, PVI 10%, prior House result 10%, incumbency 5%, generic ballot 2.5%, Trump approval 2.5%. Below the poll-count threshold, 'the polling share drops by five percentage points for each missing poll and the non-polling factors are rescaled proportionally.' For this specific PA-7 race (1 poll, well below the 6-poll threshold), the site's own displayed input-weight breakdown shows no separate polling-margin line at all: Trump Approval 3.6%, Generic Ballot 3.6%, Past Race Results 14.3%, Incumbency 7.1%, Partisan Lean 14.3%, Editorial Rating 57.1% (sums to 100%).
A27: Recency | B27: 'More recent surveys receive higher weight' in the polling average. Trump approval and the generic ballot use a rolling ~28-day sample-size-weighted window rather than the race-specific recency curve.
A28: Pollster quality | B28: No explicit per-pollster letter grade or quality score is shown on the race, forecast, or methodology pages, and no separate 'pollster ratings' page was found linked from the site. The only pollster-side adjustment described is the partisan-sponsor tag adjustment (see house_effects).
A29: House effects | B29: 'Before averaging, polls from pollsters tagged with a party sponsor, (D) or (R) in the pollster name, receive a fixed margin adjustment on the modeled values. This adjustment is applied whenever the tag is present.' Separately, when 3+ paired polls exist, Pollsmax computes 'a robust consensus margin (median Democratic minus Republican)' and downweights (but does not delete) outliers via a median-absolute-deviation (MAD) scale; with only 1 poll in this race that outlier step cannot engage.
A30: Forecast model | B30: The composite expected Democratic margin from the weighted blend of polling and fundamentals 'is converted to a win probability using a calibrated margin-to-odds curve, ... slightly steeper than a pure linear scale.' House races use 'a steeper House-specific curve' than Senate/governor. A Monte Carlo simulation (10,000 draws per House district daily) then draws 'from a normal distribution centered on a calibrated target margin' that 'blends the odds-implied margin from the composite win probability with the raw composite margin itself.' 'Simulation spread (sigma) is calibrated so the model's win probability matches anchor points at standard rating tiers; for example, roughly 95% for a safe seat and 75% for a likely seat.' The displayed race rating (e.g. 'Tilt D') is 'derived from the composite win probability using fixed probability breakpoints aligned with Pollsmax editorial tiers.'
A31: Input weights (PA-07) | B31: trump_approval_pct = 3.6; trump_approval_lean = Democratic-leaning; generic_ballot_pct = 3.6; generic_ballot_lean = Democratic-leaning; past_race_results_pct = 14.3; past_race_results_lean = Republican-leaning; incumbency_pct = 7.1; incumbency_lean = Republican-leaning; partisan_lean_pct = 14.3; partisan_lean_lean = Democratic-leaning; editorial_rating_pct = 57.1; editorial_rating_lean = None
A32: Their polling average rests on ONE poll, and that poll is Democratic-sponsored. By their own description the forecast leans mostly on fundamentals and an editorial rating rather than on polling, which is worth knowing before treating it as an independent check on the market.
A34: POLLSMAX — daily forecast trend
A35: Date | B35: Brooks win prob (model) | C35: Upper | D35: Lower | E35: Brooks vote share | F35: Mackenzie vote share | G35: Polymarket P(Dem) same day | H35: Model − market | I35: Axis label
A36: 46023 | B36: 0.5063 | C36: 0.5563 | D36: 0.4563 | E36: 0.5 | F36: 0.5 | G36: =IFERROR(IF(INDEX(Polymarket!$B$25:$B$303,MATCH($A36,Polymarket!$A$25:$A$303,0))=0,"",INDEX(Polymarket!$B$25:$B$303,MATCH($A36,Polymarket!$A$25:$A$303,0))),"") | H36: =IF(AND(ISNUMBER(B36),ISNUMBER(G36)),B36-G36,"") | I36: 01 Jan
A37: 46024 | B37: 0.5016 | C37: 0.5516 | D37: 0.4516 | E37: 0.5 | F37: 0.5 | G37: =IFERROR(IF(INDEX(Polymarket!$B$25:$B$303,MATCH($A37,Polymarket!$A$25:$A$303,0))=0,"",INDEX(Polymarket!$B$25:$B$303,MATCH($A37,Polymarket!$A$25:$A$303,0))),"") | H37: =IF(AND(ISNUMBER(B37),ISNUMBER(G37)),B37-G37,"") | I37: 02 Jan
A38: 46025 | B38: 0.5082 | C38: 0.5582 | D38: 0.4582 | E38: 0.5 | F38: 0.5 | G38: =IFERROR(IF(INDEX(Polymarket!$B$25:$B$303,MATCH($A38,Polymarket!$A$25:$A$303,0))=0,"",INDEX(Polymarket!$B$25:$B$303,MATCH($A38,Polymarket!$A$25:$A$303,0))),"") | H38: =IF(AND(ISNUMBER(B38),ISNUMBER(G38)),B38-G38,"") | I38: 03 Jan
A39: 46026 | B39: 0.5019 | C39: 0.5519 | D39: 0.4519 | E39: 0.5 | F39: 0.5 | G39: =IFERROR(IF(INDEX(Polymarket!$B$25:$B$303,MATCH($A39,Polymarket!$A$25:$A$303,0))=0,"",INDEX(Polymarket!$B$25:$B$303,MATCH($A39,Polymarket!$A$25:$A$303,0))),"") | H39: =IF(AND(ISNUMBER(B39),ISNUMBER(G39)),B39-G39,"") | I39: 04 Jan
A40: 46027 | B40: 0.4969 | C40: 0.5469 | D40: 0.4469 | E40: 0.5 | F40: 0.5 | G40: =IFERROR(IF(INDEX(Polymarket!$B$25:$B$303,MATCH($A40,Polymarket!$A$25:$A$303,0))=0,"",INDEX(Polymarket!$B$25:$B$303,MATCH($A40,Polymarket!$A$25:$A$303,0))),"") | H40: =IF(AND(ISNUMBER(B40),ISNUMBER(G40)),B40-G40,"") | I40: 05 Jan
A41: 46028 | B41: 0.5075 | C41: 0.5575 | D41: 0.4575 | E41: 0.5 | F41: 0.5 | G41: =IFERROR(IF(INDEX(Polymarket!$B$25:$B$303,MATCH($A41,Polymarket!$A$25:$A$303,0))=0,"",INDEX(Polymarket!$B$25:$B$303,MATCH($A41,Polymarket!$A$25:$A$303,0))),"") | H41: =IF(AND(ISNUMBER(B41),ISNUMBER(G41)),B41-G41,"") | I41: 06 Jan
A42: 46029 | B42: 0.5191 | C42: 0.5691 | D42: 0.4691 | E42: 0.501 | F42: 0.5 | G42: =IFERROR(IF(INDEX(Polymarket!$B$25:$B$303,MATCH($A42,Polymarket!$A$25:$A$303,0))=0,"",INDEX(Polymarket!$B$25:$B$303,MATCH($A42,Polymarket!$A$25:$A$303,0))),"") | H42: =IF(AND(ISNUMBER(B42),ISNUMBER(G42)),B42-G42,"") | I42: 07 Jan
A43: 46030 | B43: 0.5055 | C43: 0.5555 | D43: 0.4555 | E43: 0.5 | F43: 0.5 | G43: =IFERROR(IF(INDEX(Polymarket!$B$25:$B$303,MATCH($A43,Polymarket!$A$25:$A$303,0))=0,"",INDEX(Polymarket!$B$25:$B$303,MATCH($A43,Polymarket!$A$25:$A$303,0))),"") | H43: =IF(AND(ISNUMBER(B43),ISNUMBER(G43)),B43-G43,"") | I43: 08 Jan
A44: 46031 | B44: 0.5111 | C44: 0.5611 | D44: 0.4611 | E44: 0.501 | F44: 0.5 | G44: =IFERROR(IF(INDEX(Polymarket!$B$25:$B$303,MATCH($A44,Polymarket!$A$25:$A$303,0))=0,"",INDEX(Polymarket!$B$25:$B$303,MATCH($A44,Polymarket!$A$25:$A$303,0))),"") | H44: =IF(AND(ISNUMBER(B44),ISNUMBER(G44)),B44-G44,"") | I44: 09 Jan
...

Sheet Campaign Finance
A1: Campaign Finance — PA-07 (FEC)
A2: Money raised and spent in the 2026 PA-07 race, from the OpenFEC API. This is finance, not polling. Compiled 2026-10-12 02:24 UTC.
A4: COVERAGE
A5: Figures current through | B5: 2026-06-30
A6: Retrieved | B6: 2026-08-30T16:22:43Z
A8: CANDIDATE TOTALS — 2026 cycle
A9: Candidate | B9: Party | C9: Receipts | D9: Disbursements | E9: Cash on Hand | F9: Individual | G9: PAC | H9: Filed? | I9: Through
A10: Bob Brooks | B10: DEM | C10: 2392215.2 | D10: 1373792.4 | E10: 1018422.8 | F10: 1942165.5 | G10: 403000.03 | H10: yes | I10: 2026-06-30
A11: Ryan Mackenzie | B11: REP | C11: 4357405.1 | D11: 1521927.9 | E11: 2938717.2 | F11: 1493241 | G11: 1042912.8 | H11: yes | I11: 2026-06-30
A12: Frank Golden | B12: UN | H12: never filed | I12: —
A13: Aiden Alexander Gonzalez | B13: DEM | H13: never filed | I13: —
A14: Michael Ramon Granados Jr. | B14: IND | H14: never filed | I14: —
A15: Lewis Shupe | B15: IND | H15: never filed | I15: —
A16: TOTAL | C16: =SUM(C10:C15) | D16: =SUM(D10:D15) | E16: =SUM(E10:E15) | F16: =SUM(F10:F15) | G16: =SUM(G10:G15)
A18: DERIVED
A19: Cash advantage: Bob Brooks (D) - Ryan Mackenzie (R) | B19: =IFERROR(INDEX($E$10:$E$15,MATCH("Bob Brooks",$A$10:$A$15,0))-INDEX($E$10:$E$15,MATCH("Ryan Mackenzie",$A$10:$A$15,0)),"") | D19: Negative means the Republican holds more cash.
A20: Combined receipts | B20: =SUM(C10:C15)
A21: Burn rate (disbursed / raised) | B21: =IFERROR(SUM(D10:D15)/SUM(C10:C15),"")
A23: INDEPENDENT EXPENDITURES
A24: Target | B24: Support / Oppose | C24: Amount | D24: Committee | E24: As of
A25: Bob Brooks | B25: Support | C25: 140300 | D25: CONGRESSIONAL PROGRESSIVE CAUCUS PAC | E25: 2026-06-30
A26: Bob Brooks | B26: Support | C26: 3556.19 | D26: WORKING FAMILIES PARTY PAC | E26: 2026-06-30
A27: Bob Brooks | B27: Support | C27: 157.07 | D27: RURAL FREEDOM NETWORK | E27: 2026-06-30
A28: Bob Brooks | B28: Support | C28: 4500 | D28: FF PAC | E28: 2026-06-30
A29: Bob Brooks | B29: Support | C29: 99625 | D29: MEDICARE FOR ALL | E29: 2026-06-30
A30: Bob Brooks | B30: Support | C30: 30559.95 | D30: MAKE THE ROAD ACTION POLITICAL COMMITTEE | E30: 2026-06-30
A31: Bob Brooks | B31: Support | C31: 9116.67 | D31: BLUE BATTLEGROUND PROJECT | E31: 2026-06-30
